Workbook
Name 索引: #REF!

Sheet 索引
A1: 中心经营口径报表索引
A2: 序号 | B2: 索引 | C2: 报表编制说明
A3: 1 | B3: 净利简表 | C3: 1、分部及区域的预算净利及实际净利，数据来源为本文件中分部利润表、区域利润表中的预算净利润和实际净利润； 2、总监费用，预算净利数据来源为2025年中心利润表中的预算净利润及预算销售费用；实际净利为2025年中心利润表中的实际销售费用+计入到美鑫的总监工资及社保公积金费用之和； 3、因为净利简表中加了总监在美鑫的费用，所以净利简表中的汇总金额和2025年销售1中心利润表汇总有差异，差额为额外增加的这部分。
A4: 2 | B4: 所得税分摊 | C4: 1、所得税以财务口径（出库签收收入）进行计提； 2、所得税分摊的前提是基于谁受益谁承担的原则，盈利才分摊，亏损不分摊； 3、锅圈应分摊的所得税由2中心承担； 4、所得税总额为宁波味觉账面当期所得税余额，2025年销售1中心利润表中的所得税扣除锅圈承担部分的余额，两个数据有差异； 5、所得税分摊，按照各分部、区域的利润表中的正利润总额及锅圈的盈利，分别占合计利润总额的比例来分摊。
A5: 3 | B5: 2025年销售1中心利润表 | C5: 1、为中心、分部、区域的合计； 2、所得税为扣除二中心承担的税费后的余额。
A6: 4 | B6: 2025年中心利润表 | C6: 1、销售费用中为总监的费用，差旅费、招待费、样品费等挂到中心的费用。
A7: 5 | B7: 2025年江苏分部利润表 | C7: 1、营业收入的取数来源为2025年1-12月销售明细表中的金额-2025年1-12月客户计提返利的金额； 2、营业成本的取数来源为2025年1-12月销售明细表中销售结算成本+运费核对表中的运费+销售的原材料的成本； 3、税金及附加核算的是城建税、教育费附加、印花税，城建和教育费附加为当月收入的0.85%，印花税为收入的0.03%； 4、销售费用为分部人员的费用及后台职能协助挂到分部的费用（如有）； 5、所得税与所得税分摊表中数据一致。
A8: 6 | B8: 2025年浙江分部利润表 | C8: 编制规则同江苏分部利润表
A9: 7 | B9: 2025年上海分部利润表 | C9: 编制规则同江苏分部利润表
A10: 8 | B10: 2025年赣皖区域利润表 | C10: 编制规则同江苏分部利润表
A11: 9 | B11: 2025年安徽省区利润表 | C11: 编制规则同江苏分部利润表
A12: 10 | B12: 2025年江西省区利润表 | C12: 编制规则同江苏分部利润表
A13: 11 | B13: 2025年1-12月客户计提返利 | C13: 1、返利范围为经销商或有返利的直销客户，当销售额达到返利条款约定的50%时，预计很有可能实现返利的当月，开始计提返利，后续每月根据最新的销售额变动； 2、合同期限内，如果未完成返利约定销售额，该预提返利费用将冲回；如果实现返利，则该返利费用实现。
A14: 12 | B14: 产品毛利 | C14: 取数来源为2025年1-12月销售明细表
... A26: 24 | B26: 毛利率低于15%客户调整明细 | C26: 1、取数来源为ERP销售出库单列表 2、客户毛利率低于或等于15%牛油系列产品，工厂与中心五五分成毛利，调整月份为2025年5月

Sheet 收入及净利简表
A1: 销售1中心2025年各分部及区域收入&净利简表
A2: 区域 | B2: 1月 | E2: 2月 | H2: 3月 | K2: 4月 | N2: 5月 | Q2: 6月 | T2: 7月 | W2: 8月 | Z2: 9月 | AC2: 10月 | AF2: 11月 | AI2: 12月 | AL2: 合计
B3: 预算收入 | C3: 24年同期实际 | D3: 实际收入 | E3: 预算收入 | F3: 24年同期实际 | G3: 实际收入 | H3: 预算收入 | I3: 24年同期实际 | J3: 实际收入 | K3: 预算收入 | L3: 24年同期实际 | M3: 实际收入 | N3: 预算收入 | O3: 24年同期实际 | P3: 实际收入 | Q3: 预算收入 | R3: 24年同期实际 | S3: 实际收入 | T3: 预算收入 | U3: 24年同期实际 | V3: 实际收入 | W3: 预算收入 | X3: 24年同期实际 | Y3: 实际收入 | Z3: 预算收入 | AA3: 24年同期实际 | AB3: 实际收入 | AC3: 预算收入 | AD3: 24年同期实际 | AE3: 实际收入 | AF3: 预算收入 | AG3: 24年同期实际 | AH3: 实际收入 | AI3: 预算收入 | AJ3: 24年同期实际 | AK3: 实际收入 | AL3: 预算收入 | AM3: 24年同期实际 | AN3: 实际收入
A4: 江苏分部 | B4: ='2025年江苏分部利润表'!C6 -> 685500 | C4: 2214348.4 | D4: ='2025年江苏分部利润表'!D6 -> 2304694.7 | E4: ='2025年江苏分部利润表'!E6 -> 816600 | F4: 293953.61 | G4: ='2025年江苏分部利润表'!F6 -> 1666193.9 | H4: ='2025年江苏分部利润表'!G6 -> 1474500 | I4: 1021703.3 | J4: ='2025年江苏分部利润表'!H6 -> 1529599.9 | K4: ='2025年江苏分部利润表'!I6 -> 1730500 | L4: 1191870.3 | M4: ='2025年江苏分部利润表'!J6 -> 2841384.8 | N4: ='2025年江苏分部利润表'!K6 -> 1505500 | O4: 1114968.9 | P4: ='2025年江苏分部利润表'!L6 -> 2071086.5 | Q4: ='2025年江苏分部利润表'!M6 -> 1836000 | R4: 1445393.3 | S4: ='2025年江苏分部利润表'!N6 -> 2606077.2 | T4: ='2025年江苏分部利润表'!O6 -> 1948250 | U4: 1325365.9 | V4: ='2025年江苏分部利润表'!P6 -> 2343337.7 | W4: ='2025年江苏分部利润表'!Q6 -> 1944090.7 | X4: 1659134.5 | Y4: ='2025年江苏分部利润表'!R6 -> 2089992.3 | Z4: ='2025年江苏分部利润表'!S6 -> 2672284.3 | AA4: 1986844.3 | AB4: ='2025年江苏分部利润表'!T6 -> 3180499.2 | AC4: ='2025年江苏分部利润表'!U6 -> 1776275 | AD4: 1512145.6 | AE4: ='2025年江苏分部利润表'!V6 -> 1991424.3 | AF4: ='2025年江苏分部利润表'!W6 -> 2043500 | AG4: 1635695.1 | AH4: ='2025年江苏分部利润表'!X6 -> 2165174.3 | AI4: ='2025年江苏分部利润表'!Y6 -> 3781275 | AJ4: 3653965 | AK4: ='2025年江苏分部利润表'!Z6 -> 3611166.2 | AL4: =SUMIF($B$3:AK3,AL$3,$B4:$AK4) -> 22214275 | AM4: =SUMIF($B$3:AK3,AM$3,$B4:$AK4) -> 19055388 | AN4: =SUMIF($B$3:AK3,AN$3,$B4:$AK4) -> 28400631
A5: 浙江分部 | B5: ='2025年浙江分部利润表'!C6 -> 1350000 | C5: 1845184.7 | D5: ='2025年浙江分部利润表'!D6 -> 2834280.9 | E5: ='2025年浙江分部利润表'!E6 -> 1450000 | F5: 762753.83 | G5: ='2025年浙江分部利润表'!F6 -> 1525913.7 | H5: ='2025年浙江分部利润表'!G6 -> 2550000 | I5: 1399119.7 | J5: ='2025年浙江分部利润表'!H6 -> 2030623 | K5: ='2025年浙江分部利润表'!I6 -> 2550000 | L5: 1978039.7 | M5: ='2025年浙江分部利润表'!J6 -> 2478134.3 | N5: ='2025年浙江分部利润表'!K6 -> 2750000 | O5: 1891001.2 | P5: ='2025年浙江分部利润表'!L6 -> 2181764 | Q5: ='2025年浙江分部利润表'!M6 -> 2850000 | R5: 1823975.1 | S5: ='2025年浙江分部利润表'!N6 -> 2540162 | T5: ='2025年浙江分部利润表'!O6 -> 2194950 | U5: 1388214 | V5: ='2025年浙江分部利润表'!P6 -> 2153150.8 | W5: ='2025年浙江分部利润表'!Q6 -> 3059696 | X5: 2780645.8 | Y5: ='2025年浙江分部利润表'!R6 -> 3020394.8 | Z5: ='2025年浙江分部利润表'!S6 -> 3664704 | AA5: 2729408.4 | AB5: ='2025年浙江分部利润表'!T6 -> 3721151.4 | AC5: ='2025年浙江分部利润表'!U6 -> 2686850 | AD5: 3041280.1 | AE5: ='2025年浙江分部利润表'!V6 -> 2340233.6 | AF5: ='2025年浙江分部利润表'!W6 -> 2979000 | AG5: 2600701.5 | AH5: ='2025年浙江分部利润表'!X6 -> 2814572.7 | AI5: ='2025年浙江分部利润表'!Y6 -> 5599350 | AJ5: 5570531.3 | AK5: ='2025年浙江分部利润表'!Z6 -> 4295169.2 | AL5: =SUMIF($B$3:AK4,AL$3,$B5:$AK5) -> 33684550 | AM5: =SUMIF($B$3:AK4,AM$3,$B5:$AK5) -> 27810855 | AN5: =SUMIF($B$3:AK4,AN$3,$B5:$AK5) -> 31935550
A6: 上海分部 | B6: ='2025年上海分部利润表'!C6 -> 1107000 | C6: 2942728 | D6: ='2025年上海分部利润表'!D6 -> 2193436.5 | E6: ='2025年上海分部利润表'!E6 -> 1826000 | F6: 939982.31 | G6: ='2025年上海分部利润表'!F6 -> 1523858.9 | H6: ='2025年上海分部利润表'!G6 -> 3300200 | I6: 2621394.6 | J6: ='2025年上海分部利润表'!H6 -> 3225443.7 | K6: ='2025年上海分部利润表'!I6 -> 4218200 | L6: 3768174.1 | M6: ='2025年上海分部利润表'!J6 -> 3850614.7 | N6: ='2025年上海分部利润表'!K6 -> 3815800 | O6: 3026870.2 | P6: ='2025年上海分部利润表'!L6 -> 1812935.8 | Q6: ='2025年上海分部利润表'!M6 -> 3800500 | R6: 3179086.7 | S6: ='2025年上海分部利润表'!N6 -> 2841582.4 | T6: ='2025年上海分部利润表'!O6 -> 3986520 | U6: 3484218.7 | V6: ='2025年上海分部利润表'!P6 -> 2029987.8 | W6: ='2025年上海分部利润表'!Q6 -> 4575627.8 | X6: 3621668.3 | Y6: ='2025年上海分部利润表'!R6 -> 2538407.1 | Z6: ='2025年上海分部利润表'!S6 -> 5227978.2 | AA6: 4068860.3 | AB6: ='2025年上海分部利润表'!T6 -> 4157487.4 | AC6: ='2025年上海分部利润表'!U6 -> 3221313 | AD6: 2096903 | AE6: ='2025年上海分部利润表'!V6 -> 2466210.1 | AF6: ='2025年上海分部利润表'!W6 -> 4178540 | AG6: 3130654.4 | AH6: ='2025年上海分部利润表'!X6 -> 2502821.6 | AI6: ='2025年上海分部利润表'!Y6 -> 6218296 | AJ6: 6584204.5 | AK6: ='2025年上海分部利润表'!Z6 -> 3686699 | AL6: =SUMIF($B$3:AK5,AL$3,$B6:$AK6) -> 45475975 | AM6: =SUMIF($B$3:AK5,AM$3,$B6:$AK6) -> 39464745 | AN6: =SUMIF($B$3:AK5,AN$3,$B6:$AK6) -> 32829485
A7: 赣皖区域 | B7: ='2025年赣皖区域利润表'!C6 -> 844206.84 | C7: 1798560.5 | D7: ='2025年赣皖区域利润表'!D6 -> 1347836.9 | E7: ='2025年赣皖区域利润表'!E6 -> 862515 | F7: 457734.38 | G7: ='2025年赣皖区域利润表'!F6 -> 709642.25 | H7: ='2025年赣皖区域利润表'!G6 -> 1375789.3 | I7: 1003077 | J7: ='2025年赣皖区域利润表'!H6 -> 748312.86 | K7: ='2025年赣皖区域利润表'!I6 -> 1738544 | L7: 1007138.9 | M7: ='2025年赣皖区域利润表'!J6 -> 1364551 | N7: ='2025年赣皖区域利润表'!K6 -> 1499640.5 | O7: 1087571 | P7: ='2025年赣皖区域利润表'!L6 -> 741495.78 | Q7: ='2025年赣皖区域利润表'!M6 -> 1695080.5 | R7: 1001681.3 | S7: ='2025年赣皖区域利润表'!N6 -> 1166717.6 | T7: ='2025年赣皖区域利润表'!O6 -> 1733323 | U7: 1233325.3 | V7: ='2025年赣皖区域利润表'!P6 -> 949145.46 | W7: ='2025年赣皖区域利润表'!Q6 -> 1740369.5 | X7: 1470447.3 | Y7: ='2025年赣皖区域利润表'!R6 -> 1278690.5 | Z7: ='2025年赣皖区域利润表'!S6 -> 2498710.1 | AA7: 1433756.1 | AB7: ='2025年赣皖区域利润表'!T6 -> 1409395 | AC7: ='2025年赣皖区域利润表'!U6 -> 1691063.6 | AD7: 1064738.6 | AE7: ='2025年赣皖区域利润表'!V6 -> 1190690.3 | AF7: ='2025年赣皖区域利润表'!W6 -> 2064346.3 | AG7: 1220051.4 | AH7: ='2025年赣皖区域利润表'!X6 -> 1012299.1 | AI7: ='2025年赣皖区域利润表'!Y6 -> 3005004.3 | AJ7: 2083895.6 | AK7: ='2025年赣皖区域利润表'!Z6 -> 1575318.9 | AL7: =SUMIF($B$3:AK6,AL$3,$B7:$AK7) -> 20748593 | AM7: =SUMIF($B$3:AK6,AM$3,$B7:$AK7) -> 14861978 | AN7: =SUMIF($B$3:AK6,AN$3,$B7:$AK7) -> 13494096
A8: 1中心总监费用 | B8: ='2025年中心利润表 '!C6 -> 0 | C8: 0 | D8: ='2025年中心利润表 '!D6 -> 81119.48 | E8: ='2025年中心利润表 '!E6 -> 0 | F8: 0 | G8: ='2025年中心利润表 '!F6 -> 10464.61 | H8: ='2025年中心利润表 '!G6 -> 0 | I8: 0 | J8: ='2025年中心利润表 '!H6 -> 20687.61 | K8: ='2025年中心利润表 '!I6 -> 0 | L8: 0 | M8: ='2025年中心利润表 '!J6 -> 29819.47 | N8: ='2025年中心利润表 '!K6 -> 0 | O8: 0 | P8: ='2025年中心利润表 '!L6 -> 12482.3 | Q8: ='2025年中心利润表 '!M6 -> 0 | R8: 0 | S8: ='2025年中心利润表 '!N6 -> 18622.78 | T8: ='2025年中心利润表 '!O6 -> 0 | U8: 22949.092 | V8: ='2025年中心利润表 '!P6 -> 12631.64 | W8: ='2025年中心利润表 '!Q6 -> 0 | X8: 12637.168 | Y8: ='2025年中心利润表 '!R6 -> 2849.56 | Z8: ='2025年中心利润表 '!S6 -> 0 | AA8: 17894.227 | AB8: ='2025年中心利润表 '!T6 -> 11571.24 | AC8: ='2025年中心利润表 '!U6 -> 0 | AD8: 0 | AE8: ='2025年中心利润表 '!V6 -> 0 | AF8: ='2025年中心利润表 '!W6 -> 0 | AG8: 0 | AH8: ='2025年中心利润表 '!X6 -> 12910.62 | AI8: ='2025年中心利润表 '!Y6 -> 0 | AJ8: 6639.027 | AK8: ='2025年中心利润表 '!Z6 -> 5973.45 | AL8: =SUMIF($B$3:AK7,AL$3,$B8:$AK8) -> 0 | AM8: =SUMIF($B$3:AK7,AM$3,$B8:$AK8) -> 60119.514 | AN8: =SUMIF($B$3:AK7,AN$3,$B8:$AK8) -> 219132.76
A9: 合计 | B9: =SUM(B4:B8) -> 3986706.8 | C9: =SUM(C4:C8) -> 8800821.6 | D9: =SUM(D4:D8) -> 8761368.5 | E9: =SUM(E4:E8) -> 4955115 | F9: =SUM(F4:F8) -> 2454424.1 | G9: =SUM(G4:G8) -> 5436073.3 | H9: =SUM(H4:H8) -> 8700489.3 | I9: =SUM(I4:I8) -> 6045294.6 | ... AK9: =SUM(AK4:AK8) -> 13174327 | AL9: =IF(ROUND(SUMIF($B3:AK$8,AL$3,$B9:$AK9),2)=ROUND(SUM(AL4:AL8),2),ROUND(SUMIF($B3:AK$8,AL$3,$B9:$AK9),2),"Check") -> 1.2212339e+08 | AM9: =IF(ROUND(SUMIF($B3:AK$8,AM$3,$B9:$AK9),2)=ROUND(SUM(AM4:AM8),2),ROUND(SUMIF($B3:AK$8,AM$3,$B9:$AK9),2),"Check") -> 1.0125309e+08 | AN9: =IF(ROUND(SUMIF($B3:AK$8,AN$3,$B9:$AK9),2)=ROUND(SUM(AN4:AN8),2),ROUND(SUMIF($B3:AK$8,AN$3,$B9:$AK9),2),"Check") -> 1.0687889e+08
A11: 区域 | B11: 1月 | E11: 2月 | H11: 3月 | K11: 4月 | N11: 5月 | Q11: 6月 | T11: 7月 | W11: 8月 | Z11: 9月 | AC11: 10月 | AF11: 11月 | AI11: 12月 | AL11: 合计
B12: 预算净利 | C12: 24年同期实际 | D12: 实际净利 | E12: 预算净利 | F12: 24年同期实际 | G12: 实际净利 | H12: 预算净利 | I12: 24年同期实际 | J12: 实际净利 | K12: 预算净利 | L12: 24年同期实际 | M12: 实际净利 | N12: 预算净利 | O12: 24年同期实际 | P12: 实际净利 | Q12: 预算净利 | R12: 24年同期实际 | S12: 实际净利 | T12: 预算净利 | U12: 24年同期实际 | V12: 实际净利 | W12: 预算净利 | X12: 24年同期实际 | Y12: 实际净利 | Z12: 预算净利 | AA12: 24年同期实际 | AB12: 实际净利 | AC12: 预算净利 | AD12: 24年同期实际 | AE12: 实际净利 | AF12: 预算净利 | AG12: 24年同期实际 | AH12: 实际净利 | AI12: 预算净利 | AJ12: 24年同期实际 | AK12: 实际净利 | AL12: 预算净利 | AM12: 24年同期实际 | AN12: 实际净利
A13: 江苏分部 | B13: ='2025年江苏分部利润表'!C263 -> -35998.906 | C13: 195425.55 | D13: ='2025年江苏分部利润表'!D263 -> 374793.67 | E13: ='2025年江苏分部利润表'!E263 -> 4922.012 | F13: 1758.5599 | G13: ='2025年江苏分部利润表'!F263 -> 210007.03 | H13: ='2025年江苏分部利润表'!G263 -> 68700.694 | I13: 74229.994 | J13: ='2025年江苏分部利润表'!H263 -> 191036.68 | K13: ='2025年江苏分部利润表'!I263 -> 115713.75 | L13: 67104.467 | M13: ='2025年江苏分部利润表'!J263 -> 308362.78 | N13: ='2025年江苏分部利润表'!K263 -> 88941.37 | O13: 104695.28 | P13: ='2025年江苏分部利润表'!L263 -> 215840.15 | Q13: ='2025年江苏分部利润表'!M263 -> 161021.46 | R13: 109033.75 | S13: ='2025年江苏分部利润表'!N263 -> 341174.48 | T13: ='2025年江苏分部利润表'!O263 -> 188428.17 | U13: 172924.77 | V13: ='2025年江苏分部利润表'!P263 -> 251237.75 | W13: ='2025年江苏分部利润表'!Q263 -> 150857.06 | X13: 220602.39 | Y13: ='2025年江苏分部利润表'!R263 -> 268253.22 | Z13: ='2025年江苏分部利润表'!S263 -> 234551.16 | AA13: 270301.82 | AB13: ='2025年江苏分部利润表'!T263 -> 460909 | AC13: ='2025年江苏分部利润表'!U263 -> 122217.84 | AD13: 147891.71 | AE13: ='2025年江苏分部利润表'!V263 -> 261060.5 | AF13: ='2025年江苏分部利润表'!W263 -> 190494.74 | AG13: 189470.49 | AH13: ='2025年江苏分部利润表'!X263 -> 298202.12 | AI13: ='2025年江苏分部利润表'!Y263 -> 525986.93 | AJ13: 490380.3 | AK13: ='2025年江苏分部利润表'!Z263 -> 590435.63 | AL13: =SUMIF($B$12:AK12,AL$12,$B13:$AK13) -> 1815836.3 | AM13: =SUMIF($B$12:AK12,AM$12,$B13:$AK13) -> 2043819.1 | AN13: =SUMIF($B$12:AK12,AN$12,$B13:$AK13) -> 3771313
A14: 浙江分部 | B14: ='2025年浙江分部利润表'!C263 -> -10700.666 | C14: 168110.41 | D14: ='2025年浙江分部利润表'!D263 -> 242231.09 | E14: ='2025年浙江分部利润表'!E263 -> 28309.249 | F14: 24020.712 | G14: ='2025年浙江分部利润表'!F263 -> 148009.2 | H14: ='2025年浙江分部利润表'!G263 -> 146442.68 | I14: 98486.204 | J14: ='2025年浙江分部利润表'!H263 -> 257658.82 | K14: ='2025年浙江分部利润表'!I263 -> 157069.51 | L14: 126772.95 | M14: ='2025年浙江分部利润表'!J263 -> 238152.41 | N14: ='2025年浙江分部利润表'!K263 -> 185095.24 | O14: 54806.128 | P14: ='2025年浙江分部利润表'!L263 -> 236799.47 | Q14: ='2025年浙江分部利润表'!M263 -> 199869.06 | R14: 148730.56 | S14: ='2025年浙江分部利润表'!N263 -> 293683.55 | T14: ='2025年浙江分部利润表'!O263 -> 52040.946 | U14: 128101.79 | V14: ='2025年浙江分部利润表'!P263 -> 202467.84 | W14: ='2025年浙江分部利润表'!Q263 -> 210383.21 | X14: 430278.5 | Y14: ='2025年浙江分部利润表'!R263 -> 321456.86 | Z14: ='2025年浙江分部利润表'!S263 -> 229663.48 | AA14: 341502.04 | AB14: ='2025年浙江分部利润表'!T263 -> 480667.58 | AC14: ='2025年浙江分部利润表'!U263 -> 149115.67 | AD14: 356255.91 | AE14: ='2025年浙江分部利润表'!V263 -> 356088.61 | AF14: ='2025年浙江分部利润表'!W263 -> 206122.96 | AG14: 262567.3 | AH14: ='2025年浙江分部利润表'!X263 -> 409662.21 | AI14: ='2025年浙江分部利润表'!Y263 -> 706966.16 | AJ14: 776097.07 | AK14: ='2025年浙江分部利润表'!Z263 -> 642245.05 | AL14: =SUMIF($B$12:AK13,AL$12,$B14:$AK14) -> 2260377.5 | AM14: =SUMIF($B$12:AK13,AM$12,$B14:$AK14) -> 2915729.6 | AN14: =SUMIF($B$12:AK13,AN$12,$B14:$AK14) -> 3829122.7
A15: 上海分部 | B15: ='2025年上海分部利润表'!C263 -> -107697.31 | C15: 338485.51 | D15: ='2025年上海分部利润表'!D263 -> 263950.01 | E15: ='2025年上海分部利润表'!E263 -> 78164.49 | F15: 34440.646 | G15: ='2025年上海分部利润表'!F263 -> 224899.54 | H15: ='2025年上海分部利润表'!G263 -> 267281.5 | I15: 248020.21 | J15: ='2025年上海分部利润表'!H263 -> 441132.29 | K15: ='2025年上海分部利润表'!I263 -> 476749.98 | L15: 412791.16 | M15: ='2025年上海分部利润表'!J263 -> 483311.62 | N15: ='2025年上海分部利润表'!K263 -> 373734.63 | O15: 330920.11 | P15: ='2025年上海分部利润表'!L263 -> 249248.8 | Q15: ='2025年上海分部利润表'!M263 -> 362498.94 | R15: 335690.99 | S15: ='2025年上海分部利润表'!N263 -> 438192.76 | T15: ='2025年上海分部利润表'!O263 -> 306559.91 | U15: 486536.23 | V15: ='2025年上海分部利润表'!P263 -> 325454.58 | W15: ='2025年上海分部利润表'!Q263 -> 458525.46 | X15: 530868.17 | Y15: ='2025年上海分部利润表'!R263 -> 488285.28 | Z15: ='2025年上海分部利润表'!S263 -> 568259.29 | AA15: 503556.66 | AB15: ='2025年上海分部利润表'!T263 -> 740815.08 | AC15: ='2025年上海分部利润表'!U263 -> 217650.09 | AD15: 332455.74 | AE15: ='2025年上海分部利润表'!V263 -> 387192.84 | AF15: ='2025年上海分部利润表'!W263 -> 417019.95 | AG15: 381189.7 | AH15: ='2025年上海分部利润表'!X263 -> 314474.28 | AI15: ='2025年上海分部利润表'!Y263 -> 786693.62 | AJ15: 1039667.2 | AK15: ='2025年上海分部利润表'!Z263 -> 620728.41 | AL15: =SUMIF($B$12:AK14,AL$12,$B15:$AK15) -> 4205440.5 | AM15: =SUMIF($B$12:AK14,AM$12,$B15:$AK15) -> 4974622.3 | AN15: =SUMIF($B$12:AK14,AN$12,$B15:$AK15) -> 4977685.5
A16: 赣皖区域 | B16: ='2025年赣皖区域利润表'!C263 -> 28385.02 | C16: 155935.15 | D16: ='2025年赣皖区域利润表'!D263 -> 203946.75 | E16: ='2025年赣皖区域利润表'!E263 -> 14933.286 | F16: -35150.085 | G16: ='2025年赣皖区域利润表'!F263 -> 66296.761 | H16: ='2025年赣皖区域利润表'!G263 -> 77576.08 | I16: -15348.141 | J16: ='2025年赣皖区域利润表'!H263 -> 6519.5442 | K16: ='2025年赣皖区域利润表'!I263 -> 167572.61 | L16: -11596.191 | M16: ='2025年赣皖区域利润表'!J263 -> 188278.89 | N16: ='2025年赣皖区域利润表'!K263 -> 122534.39 | O16: -27051.04 | P16: ='2025年赣皖区域利润表'!L263 -> 38301.917 | Q16: ='2025年赣皖区域利润表'!M263 -> 164008.1 | R16: -33985.336 | S16: ='2025年赣皖区域利润表'!N263 -> 175806.16 | T16: ='2025年赣皖区域利润表'!O263 -> 174993.24 | U16: 24834.659 | V16: ='2025年赣皖区域利润表'!P263 -> 150623.35 | W16: ='2025年赣皖区域利润表'!Q263 -> 167896.32 | X16: 111484.92 | Y16: ='2025年赣皖区域利润表'!R263 -> 195980.67 | Z16: ='2025年赣皖区域利润表'!S263 -> 282779.5 | AA16: 70491.287 | AB16: ='2025年赣皖区域利润表'!T263 -> 206798.58 | AC16: ='2025年赣皖区域利润表'!U263 -> 146567.41 | AD16: -10086.552 | AE16: ='2025年赣皖区域利润表'!V263 -> 214034.25 | AF16: ='2025年赣皖区域利润表'!W263 -> 244024.15 | AG16: 85390.763 | AH16: ='2025年赣皖区域利润表'!X263 -> 152165.2 | AI16: ='2025年赣皖区域利润表'!Y263 -> 432847.69 | AJ16: 272419.3 | AK16: ='2025年赣皖区域利润表'!Z263 -> 300126.77 | AL16: =SUMIF($B$12:AK15,AL$12,$B16:$AK16) -> 2024117.8 | AM16: =SUMIF($B$12:AK15,AM$12,$B16:$AK16) -> 587338.74 | AN16: =SUMIF($B$12:AK15,AN$12,$B16:$AK16) -> 1898878.8
A17: 1中心总监费用 | B17: ='2025年中心利润表 '!C263 -> -44818.64 | C17: -65461.455 | D17: ='2025年中心利润表 '!D263 -> -20457.675 | E17: ='2025年中心利润表 '!E263 -> -31652.8 | F17: -53686.084 | G17: ='2025年中心利润表 '!F263 -> -42905.844 | H17: ='2025年中心利润表 '!G263 -> -42310.19 | I17: -72907.66 | J17: ='2025年中心利润表 '!H263 -> 50374.048 | K17: ='2025年中心利润表 '!I263 -> -46685.83 | L17: -34657.503 | M17: ='2025年中心利润表 '!J263 -> -22108.105 | N17: ='2025年中心利润表 '!K263 -> -44255.84 | O17: -45424.378 | P17: ='2025年中心利润表 '!L263 -> -4723.9119 | Q17: ='2025年中心利润表 '!M263 -> -46437.06 | R17: -47604.856 | S17: ='2025年中心利润表 '!N263 -> -3145.9164 | T17: ='2025年中心利润表 '!O263 -> -48740.24 | U17: -47817.125 | V17: ='2025年中心利润表 '!P263 -> -8631.7206 | W17: ='2025年中心利润表 '!Q263 -> -52371.55 | X17: -52718.158 | Y17: ='2025年中心利润表 '!R265 -> -7390.9408 | Z17: ='2025年中心利润表 '!S263 -> -61330.37 | AA17: -45985.22 | AB17: ='2025年中心利润表 '!T263 -> -16701.197 | AC17: ='2025年中心利润表 '!U263 -> -52458.11 | AD17: -50854.778 | AE17: ='2025年中心利润表 '!V263 -> -8644.85 | AF17: ='2025年中心利润表 '!W263 -> -55890.62 | AG17: -59095.019 | AH17: ='2025年中心利润表 '!X263 -> -6380.4009 | AI17: ='2025年中心利润表 '!Y263 -> -72508.75 | AJ17: -52353.118 | AK17: ='2025年中心利润表 '!Z263 -> -18237.458 | AL17: =SUMIF($B$12:AK16,AL$12,$B17:$AK17) -> -599460 | AM17: =SUMIF($B$12:AK16,AM$12,$B17:$AK17) -> -628565.36 | AN17: =SUMIF($B$12:AK16,AN$12,$B17:$AK17) -> -108953.97
A18: 合计 | B18: =SUM(B13:B17) -> -170830.51 | C18: =SUM(C13:C17) -> 792495.17 | D18: =SUM(D13:D17) -> 1064463.9 | E18: =SUM(E13:E17) -> 94676.237 | F18: =SUM(F13:F17) -> -28616.251 | G18: =SUM(G13:G17) -> 606306.68 | H18: =SUM(H13:H17) -> 517690.76 | I18: =SUM(I13:I17) -> 332480.6 | ... AK18: =SUM(AK13:AK17) -> 2135298.4 | AL18: =IF(ROUND(SUMIF($B$12:AK17,AL$12,$B18:$AK18),2)=ROUND(SUM(AL13:AL17),2),ROUND(SUMIF($B$12:AK17,AL$12,$B18:$AK18),2),"Check") -> 9706312.1 | AM18: =IF(ROUND(SUMIF($B$12:AK17,AM$12,$B18:$AK18),2)=ROUND(SUM(AM13:AM17),2),ROUND(SUMIF($B$12:AK17,AM$12,$B18:$AK18),2),"Check") -> 9892944.3 | AN18: =IF(ROUND(SUMIF($B$12:AK17,AN$12,$B18:$AK18),2)=ROUND(SUM(AN13:AN17),2),ROUND(SUMIF($B$12:AK17,AN$12,$B18:$AK18),2),"Check") -> 14368046
A19: 备注：
A20: 本表收入为扣除返利后收入，利润为分红前利润，与销售1中心利润表中收入及净利润数据相等；
A21: 1中心总监费用：是指包含该总监报销与业务相关的差旅、招待、样品费等发生的一切费用，也包含其工资、社保及宁波味觉发生的残疾人工资及社保等；
A22: 目的：主要是表明该BU下总体净利完成情况（即该公司组织目标净利的完成情况）
A23: 编制说明： | B23: =索引!C3 -> 1、分部及区域的预算净利及实际净利，数据来源为本文件中分部利润表、区域利润表中的预算净利润和实际净利润； 2、总监费用，预算净利数据来源为2025年中心利润表中的预算净利润及预算销售费用；实际净利为2025年中心利润表中的实际销售费用+计入到美鑫的总监工资及社保公积金费用之和； 3、因为净利简表中加了总监在美鑫的费用，所以净利简表中的汇总金额和2025年销售1中心利润表汇总有差异，差额为额外增加的这部分。
W24: 0 | Y24: 0 | Z24: 0 | AB24: 0 | AC24: 0 | AE24: 0 | AF24: 0 | AH24: 0 | AI24: 0 | AK24: 0

Sheet 2025年销售1中心利润表
A1: 宁波味觉销售1中心利润表
A2: 46021 | AB2: 会企01表
A3: 编制单位：江苏美鑫食品科技有限公司 | AB3: 单位：元
A4: 项 目 | B4: 行次 | C4: 45658 | E4: 45689 | G4: 45717 | I4: 45748 | K4: 45778 | M4: 45809 | O4: 45839 | Q4: 45870 | S4: 45901 | U4: 45931 | W4: 45962 | Y4: 45992 | AA4: 2025年合计 | AD4: 2025年合计逆向验证 | AF4: 检验结果
C5: 预算数 | D5: 本月实际 | E5: 预算数 | F5: 本月实际 | G5: 预算数 | H5: 本月实际 | I5: 预算数 | J5: 本月实际 | K5: 预算数 | L5: 本月实际 | M5: 预算数 | N5: 本月实际 | O5: 预算数 | P5: 本月实际 | Q5: 预算数 | R5: 本月实际 | S5: 预算数 | T5: 本月实际 | U5: 预算数 | V5: 本月实际 | W5: 预算数 | X5: 本月实际 | Y5: 预算数 | Z5: 本月实际 | AA5: 预算数 | AB5: 本年实际 | AD5: 预算数 | AE5: 本月实际 | AF5: 预算数 | AG5: 本月实际
A6: 一、营业收入 | B6: 1 | C6: =SUM(C7:C13,C15,-C14) -> 3986706.8 | D6: =SUM(D7:D13,D15,-D14) -> 8761368.5 | E6: =SUM(E7:E13,E15,-E14) -> 4955115 | F6: =SUM(F7:F13,F15,-F14) -> 5436073.3 | G6: =SUM(G7:G13,G15,-G14) -> 8700489.3 | H6: =SUM(H7:H13,H15,-H14) -> 7554667 | I6: =SUM(I7:I13,I15,-I14) -> 10237244 | J6: =SUM(J7:J13,J15,-J14) -> 10564504 | ... Z6: =SUM(Z7:Z13,Z15,-Z14) -> 13174327 | AA6: =C6+E6+G6+I6+K6+M6+O6+Q6+S6+U6+W6+Y6 -> 1.2212339e+08 | AB6: =D6+F6+H6+J6+L6+N6+P6+R6+T6+V6+X6+Z6 -> 1.0687889e+08 | AD6: =SUMIF($C$5:$Z$5,$AD$5,C6:Z6) -> 1.2212339e+08 | AE6: =SUMIF($C$5:$Z$5,$AD$5,D6:AA6) -> 1.0687889e+08 | AF6: =AA6-AD6 -> 0 | AG6: =AB6-AE6 -> 0 | AH6: =SUM('[1]2024年全面预算利润表 (销售1中心)2.8亿'!E10:H10) -> 36318373
A7: 中式汤底 | C7: ='2025年中心利润表 '!C7+'2025年江苏分部利润表'!C7+'2025年浙江分部利润表'!C7+'2025年上海分部利润表'!C7+'2025年赣皖区域利润表'!C7 -> 0 | D7: ='2025年中心利润表 '!D7+'2025年江苏分部利润表'!D7+'2025年浙江分部利润表'!D7+'2025年上海分部利润表'!D7+'2025年赣皖区域利润表'!D7 -> 2200703.1 | E7: ='2025年中心利润表 '!E7+'2025年江苏分部利润表'!E7+'2025年浙江分部利润表'!E7+'2025年上海分部利润表'!E7+'2025年赣皖区域利润表'!E7 -> 0 | F7: ='2025年中心利润表 '!F7+'2025年江苏分部利润表'!F7+'2025年浙江分部利润表'!F7+'2025年上海分部利润表'!F7+'2025年赣皖区域利润表'!F7 -> 1492040.9 | G7: ='2025年中心利润表 '!G7+'2025年江苏分部利润表'!G7+'2025年浙江分部利润表'!G7+'2025年上海分部利润表'!G7+'2025年赣皖区域利润表'!G7 -> 0 | H7: ='2025年中心利润表 '!H7+'2025年江苏分部利润表'!H7+'2025年浙江分部利润表'!H7+'2025年上海分部利润表'!H7+'2025年赣皖区域利润表'!H7 -> 2480280.4 | I7: ='2025年中心利润表 '!I7+'2025年江苏分部利润表'!I7+'2025年浙江分部利润表'!I7+'2025年上海分部利润表'!I7+'2025年赣皖区域利润表'!I7 -> 0 | J7: ='2025年中心利润表 '!J7+'2025年江苏分部利润表'!J7+'2025年浙江分部利润表'!J7+'2025年上海分部利润表'!J7+'2025年赣皖区域利润表'!J7 -> 3379438.1 | ... Z7: ='2025年中心利润表 '!Z7+'2025年江苏分部利润表'!Z7+'2025年浙江分部利润表'!Z7+'2025年上海分部利润表'!Z7+'2025年赣皖区域利润表'!Z7 -> 3645704.4 | AA7: =C7+E7+G7+I7+K7+M7+O7+Q7+S7+U7+W7+Y7 -> 0 | AB7: =D7+F7+H7+J7+L7+N7+P7+R7+T7+V7+X7+Z7 -> 31715084 | AD7: =SUMIF($C$5:$Z$5,$AD$5,C7:Z7) -> 0 | AE7: =SUMIF($C$5:$Z$5,$AD$5,D7:AA7) -> 31715084 | AF7: =AA7-AD7 -> 0 | AG7: =AB7-AE7 -> 0 | AH7: =SUM('[1]2024年全面预算利润表 (销售1中心)2.8亿'!E11:H11) -> 0
A8: 酱料 | C8: ='2025年中心利润表 '!C8+'2025年江苏分部利润表'!C8+'2025年浙江分部利润表'!C8+'2025年上海分部利润表'!C8+'2025年赣皖区域利润表'!C8 -> 0 | D8: ='2025年中心利润表 '!D8+'2025年江苏分部利润表'!D8+'2025年浙江分部利润表'!D8+'2025年上海分部利润表'!D8+'2025年赣皖区域利润表'!D8 -> 3250736.1 | E8: ='2025年中心利润表 '!E8+'2025年江苏分部利润表'!E8+'2025年浙江分部利润表'!E8+'2025年上海分部利润表'!E8+'2025年赣皖区域利润表'!E8 -> 0 | F8: ='2025年中心利润表 '!F8+'2025年江苏分部利润表'!F8+'2025年浙江分部利润表'!F8+'2025年上海分部利润表'!F8+'2025年赣皖区域利润表'!F8 -> 2154126 | G8: ='2025年中心利润表 '!G8+'2025年江苏分部利润表'!G8+'2025年浙江分部利润表'!G8+'2025年上海分部利润表'!G8+'2025年赣皖区域利润表'!G8 -> 0 | H8: ='2025年中心利润表 '!H8+'2025年江苏分部利润表'!H8+'2025年浙江分部利润表'!H8+'2025年上海分部利润表'!H8+'2025年赣皖区域利润表'!H8 -> 3353359 | I8: ='2025年中心利润表 '!I8+'2025年江苏分部利润表'!I8+'2025年浙江分部利润表'!I8+'2025年上海分部利润表'!I8+'2025年赣皖区域利润表'!I8 -> 0 | J8: ='2025年中心利润表 '!J8+'2025年江苏分部利润表'!J8+'2025年浙江分部利润表'!J8+'2025年上海分部利润表'!J8+'2025年赣皖区域利润表'!J8 -> 3782684 | ... Z8: ='2025年中心利润表 '!Z8+'2025年江苏分部利润表'!Z8+'2025年浙江分部利润表'!Z8+'2025年上海分部利润表'!Z8+'2025年赣皖区域利润表'!Z8 -> 5165091 | AA8: =C8+E8+G8+I8+K8+M8+O8+Q8+S8+U8+W8+Y8 -> 0 | AB8: =D8+F8+H8+J8+L8+N8+P8+R8+T8+V8+X8+Z8 -> 40157217 | AD8: =SUMIF($C$5:$Z$5,$AD$5,C8:Z8) -> 0 | AE8: =SUMIF($C$5:$Z$5,$AD$5,D8:AA8) -> 40157217 | AF8: =AA8-AD8 -> 0 | AG8: =AB8-AE8 -> 0 | AH8: =SUM('[1]2024年全面预算利润表 (销售1中心)2.8亿'!E12:H12) -> 0
A9: 川味底料 | C9: ='2025年中心利润表 '!C9+'2025年江苏分部利润表'!C9+'2025年浙江分部利润表'!C9+'2025年上海分部利润表'!C9+'2025年赣皖区域利润表'!C9 -> 0 | D9: ='2025年中心利润表 '!D9+'2025年江苏分部利润表'!D9+'2025年浙江分部利润表'!D9+'2025年上海分部利润表'!D9+'2025年赣皖区域利润表'!D9 -> 2575914.4 | E9: ='2025年中心利润表 '!E9+'2025年江苏分部利润表'!E9+'2025年浙江分部利润表'!E9+'2025年上海分部利润表'!E9+'2025年赣皖区域利润表'!E9 -> 0 | F9: ='2025年中心利润表 '!F9+'2025年江苏分部利润表'!F9+'2025年浙江分部利润表'!F9+'2025年上海分部利润表'!F9+'2025年赣皖区域利润表'!F9 -> 1516933.9 | G9: ='2025年中心利润表 '!G9+'2025年江苏分部利润表'!G9+'2025年浙江分部利润表'!G9+'2025年上海分部利润表'!G9+'2025年赣皖区域利润表'!G9 -> 0 | H9: ='2025年中心利润表 '!H9+'2025年江苏分部利润表'!H9+'2025年浙江分部利润表'!H9+'2025年上海分部利润表'!H9+'2025年赣皖区域利润表'!H9 -> 1354693.2 | I9: ='2025年中心利润表 '!I9+'2025年江苏分部利润表'!I9+'2025年浙江分部利润表'!I9+'2025年上海分部利润表'!I9+'2025年赣皖区域利润表'!I9 -> 0 | J9: ='2025年中心利润表 '!J9+'2025年江苏分部利润表'!J9+'2025年浙江分部利润表'!J9+'2025年上海分部利润表'!J9+'2025年赣皖区域利润表'!J9 -> 2686716.9 | ... Z9: ='2025年中心利润表 '!Z9+'2025年江苏分部利润表'!Z9+'2025年浙江分部利润表'!Z9+'2025年上海分部利润表'!Z9+'2025年赣皖区域利润表'!Z9 -> 4042992.6 | AA9: =C9+E9+G9+I9+K9+M9+O9+Q9+S9+U9+W9+Y9 -> 0 | AB9: =D9+F9+H9+J9+L9+N9+P9+R9+T9+V9+X9+Z9 -> 29180682 | AD9: =SUMIF($C$5:$Z$5,$AD$5,C9:Z9) -> 0 | AE9: =SUMIF($C$5:$Z$5,$AD$5,D9:AA9) -> 29180682 | AF9: =AA9-AD9 -> 0 | AG9: =AB9-AE9 -> 0 | AH9: =SUM('[1]2024年全面预算利润表 (销售1中心)2.8亿'!E13:H13) -> 0
A10: 调味汁 | C10: ='2025年中心利润表 '!C10+'2025年江苏分部利润表'!C10+'2025年浙江分部利润表'!C10+'2025年上海分部利润表'!C10+'2025年赣皖区域利润表'!C10 -> 0 | D10: ='2025年中心利润表 '!D10+'2025年江苏分部利润表'!D10+'2025年浙江分部利润表'!D10+'2025年上海分部利润表'!D10+'2025年赣皖区域利润表'!D10 -> 385252.79 | E10: ='2025年中心利润表 '!E10+'2025年江苏分部利润表'!E10+'2025年浙江分部利润表'!E10+'2025年上海分部利润表'!E10+'2025年赣皖区域利润表'!E10 -> 0 | F10: ='2025年中心利润表 '!F10+'2025年江苏分部利润表'!F10+'2025年浙江分部利润表'!F10+'2025年上海分部利润表'!F10+'2025年赣皖区域利润表'!F10 -> 159188.91 | G10: ='2025年中心利润表 '!G10+'2025年江苏分部利润表'!G10+'2025年浙江分部利润表'!G10+'2025年上海分部利润表'!G10+'2025年赣皖区域利润表'!G10 -> 0 | H10: ='2025年中心利润表 '!H10+'2025年江苏分部利润表'!H10+'2025年浙江分部利润表'!H10+'2025年上海分部利润表'!H10+'2025年赣皖区域利润表'!H10 -> 223817.74 | I10: ='2025年中心利润表 '!I10+'2025年江苏分部利润表'!I10+'2025年浙江分部利润表'!I10+'2025年上海分部利润表'!I10+'2025年赣皖区域利润表'!I10 -> 0 | J10: ='2025年中心利润表 '!J10+'2025年江苏分部利润表'!J10+'2025年浙江分部利润表'!J10+'2025年上海分部利润表'!J10+'2025年赣皖区域利润表'!J10 -> 407827.34 | ... Z10: ='2025年中心利润表 '!Z10+'2025年江苏分部利润表'!Z10+'2025年浙江分部利润表'!Z10+'2025年上海分部利润表'!Z10+'2025年赣皖区域利润表'!Z10 -> 282549.15 | AA10: =C10+E10+G10+I10+K10+M10+O10+Q10+S10+U10+W10+Y10 -> 0 | AB10: =D10+F10+H10+J10+L10+N10+P10+R10+T10+V10+X10+Z10 -> 3882508.7 | AD10: =SUMIF($C$5:$Z$5,$AD$5,C10:Z10) -> 0 | AE10: =SUMIF($C$5:$Z$5,$AD$5,D10:AA10) -> 3882508.7 | AF10: =AA10-AD10 -> 0 | AG10: =AB10-AE10 -> 0 | AH10: =SUM('[1]2024年全面预算利润表 (销售1中心)2.8亿'!E14:H14) -> 36318373
A11: 复合调味粉 | C11: ='2025年中心利润表 '!C11+'2025年江苏分部利润表'!C11+'2025年浙江分部利润表'!C11+'2025年上海分部利润表'!C11+'2025年赣皖区域利润表'!C11 -> 0 | D11: ='2025年中心利润表 '!D11+'2025年江苏分部利润表'!D11+'2025年浙江分部利润表'!D11+'2025年上海分部利润表'!D11+'2025年赣皖区域利润表'!D11 -> 296240.26 | E11: ='2025年中心利润表 '!E11+'2025年江苏分部利润表'!E11+'2025年浙江分部利润表'!E11+'2025年上海分部利润表'!E11+'2025年赣皖区域利润表'!E11 -> 0 | F11: ='2025年中心利润表 '!F11+'2025年江苏分部利润表'!F11+'2025年浙江分部利润表'!F11+'2025年上海分部利润表'!F11+'2025年赣皖区域利润表'!F11 -> 88575.066 | G11: ='2025年中心利润表 '!G11+'2025年江苏分部利润表'!G11+'2025年浙江分部利润表'!G11+'2025年上海分部利润表'!G11+'2025年赣皖区域利润表'!G11 -> 0 | H11: ='2025年中心利润表 '!H11+'2025年江苏分部利润表'!H11+'2025年浙江分部利润表'!H11+'2025年上海分部利润表'!H11+'2025年赣皖区域利润表'!H11 -> 110596.07 | I11: ='2025年中心利润表 '!I11+'2025年江苏分部利润表'!I11+'2025年浙江分部利润表'!I11+'2025年上海分部利润表'!I11+'2025年赣皖区域利润表'!I11 -> 0 | J11: ='2025年中心利润表 '!J11+'2025年江苏分部利润表'!J11+'2025年浙江分部利润表'!J11+'2025年上海分部利润表'!J11+'2025年赣皖区域利润表'!J11 -> 370984.69 | ... Z11: ='2025年中心利润表 '!Z11+'2025年江苏分部利润表'!Z11+'2025年浙江分部利润表'!Z11+'2025年上海分部利润表'!Z11+'2025年赣皖区域利润表'!Z11 -> 106234.98 | AA11: =C11+E11+G11+I11+K11+M11+O11+Q11+S11+U11+W11+Y11 -> 0 | AB11: =D11+F11+H11+J11+L11+N11+P11+R11+T11+V11+X11+Z11 -> 2557362.6 | AD11: =SUMIF($C$5:$Z$5,$AD$5,C11:Z11) -> 0 | AE11: =SUMIF($C$5:$Z$5,$AD$5,D11:AA11) -> 2557362.6 | AF11: =AA11-AD11 -> 0 | AG11: =AB11-AE11 -> 0 | AH11: =SUM('[1]2024年全面预算利润表 (销售1中心)2.8亿'!E15:H15) -> 0
A12: 团餐 | C12: ='2025年中心利润表 '!C12+'2025年江苏分部利润表'!C12+'2025年浙江分部利润表'!C12+'2025年上海分部利润表'!C12+'2025年赣皖区域利润表'!C12 -> 0 | D12: ='2025年中心利润表 '!D12+'2025年江苏分部利润表'!D12+'2025年浙江分部利润表'!D12+'2025年上海分部利润表'!D12+'2025年赣皖区域利润表'!D12 -> 7176.7404 | E12: ='2025年中心利润表 '!E12+'2025年江苏分部利润表'!E12+'2025年浙江分部利润表'!E12+'2025年上海分部利润表'!E12+'2025年赣皖区域利润表'!E12 -> 0 | F12: ='2025年中心利润表 '!F12+'2025年江苏分部利润表'!F12+'2025年浙江分部利润表'!F12+'2025年上海分部利润表'!F12+'2025年赣皖区域利润表'!F12 -> 15717.434 | G12: ='2025年中心利润表 '!G12+'2025年江苏分部利润表'!G12+'2025年浙江分部利润表'!G12+'2025年上海分部利润表'!G12+'2025年赣皖区域利润表'!G12 -> 0 | H12: ='2025年中心利润表 '!H12+'2025年江苏分部利润表'!H12+'2025年浙江分部利润表'!H12+'2025年上海分部利润表'!H12+'2025年赣皖区域利润表'!H12 -> 11089.57 | I12: ='2025年中心利润表 '!I12+'2025年江苏分部利润表'!I12+'2025年浙江分部利润表'!I12+'2025年上海分部利润表'!I12+'2025年赣皖区域利润表'!I12 -> 0 | J12: ='2025年中心利润表 '!J12+'2025年江苏分部利润表'!J12+'2025年浙江分部利润表'!J12+'2025年上海分部利润表'!J12+'2025年赣皖区域利润表'!J12 -> 7029.5472 | ... Z12: ='2025年中心利润表 '!Z12+'2025年江苏分部利润表'!Z12+'2025年浙江分部利润表'!Z12+'2025年上海分部利润表'!Z12+'2025年赣皖区域利润表'!Z12 -> 10082.891 | AA12: =C12+E12+G12+I12+K12+M12+O12+Q12+S12+U12+W12+Y12 -> 0 | AB12: =D12+F12+H12+J12+L12+N12+P12+R12+T12+V12+X12+Z12 -> 70994.923 | AD12: =SUMIF($C$5:$Z$5,$AD$5,C12:Z12) -> 0 | AE12: =SUMIF($C$5:$Z$5,$AD$5,D12:AA12) -> 70994.923 | AF12: =AA12-AD12 -> 0 | AG12: =AB12-AE12 -> 0 | AH12: =SUM('[1]2024年全面预算利润表 (销售1中心)2.8亿'!E16:H16) -> 29585058
A13: 预制菜 | C13: ='2025年中心利润表 '!C13+'2025年江苏分部利润表'!C13+'2025年浙江分部利润表'!C13+'2025年上海分部利润表'!C13+'2025年赣皖区域利润表'!C13 -> 0 | D13: ='2025年中心利润表 '!D13+'2025年江苏分部利润表'!D13+'2025年浙江分部利润表'!D13+'2025年上海分部利润表'!D13+'2025年赣皖区域利润表'!D13 -> 44491.173 | E13: ='2025年中心利润表 '!E13+'2025年江苏分部利润表'!E13+'2025年浙江分部利润表'!E13+'2025年上海分部利润表'!E13+'2025年赣皖区域利润表'!E13 -> 0 | F13: ='2025年中心利润表 '!F13+'2025年江苏分部利润表'!F13+'2025年浙江分部利润表'!F13+'2025年上海分部利润表'!F13+'2025年赣皖区域利润表'!F13 -> 8960.19 | G13: ='2025年中心利润表 '!G13+'2025年江苏分部利润表'!G13+'2025年浙江分部利润表'!G13+'2025年上海分部利润表'!G13+'2025年赣皖区域利润表'!G13 -> 0 | H13: ='2025年中心利润表 '!H13+'2025年江苏分部利润表'!H13+'2025年浙江分部利润表'!H13+'2025年上海分部利润表'!H13+'2025年赣皖区域利润表'!H13 -> 20830.952 | I13: ='2025年中心利润表 '!I13+'2025年江苏分部利润表'!I13+'2025年浙江分部利润表'!I13+'2025年上海分部利润表'!I13+'2025年赣皖区域利润表'!I13 -> 0 | J13: ='2025年中心利润表 '!J13+'2025年江苏分部利润表'!J13+'2025年浙江分部利润表'!J13+'2025年上海分部利润表'!J13+'2025年赣皖区域利润表'!J13 -> 22105.362 | ... Z13: ='2025年中心利润表 '!Z13+'2025年江苏分部利润表'!Z13+'2025年浙江分部利润表'!Z13+'2025年上海分部利润表'!Z13+'2025年赣皖区域利润表'!Z13 -> 5973.45 | AA13: =C13+E13+G13+I13+K13+M13+O13+Q13+S13+U13+W13+Y13 -> 0 | AB13: =D13+F13+H13+J13+L13+N13+P13+R13+T13+V13+X13+Z13 -> 203664.82 | AD13: =SUMIF($C$5:$Z$5,$AD$5,C13:Z13) -> 0 | AE13: =SUMIF($C$5:$Z$5,$AD$5,D13:AA13) -> 203664.82 | AF13: =AA13-AD13 -> 0 | AG13: =AB13-AE13 -> 0 | AH13: =SUM('[1]2024年全面预算利润表 (销售1中心)2.8亿'!E17:H17) -> 0
A14: 返利 | C14: ='2025年中心利润表 '!C14+'2025年江苏分部利润表'!C14+'2025年浙江分部利润表'!C14+'2025年上海分部利润表'!C14+'2025年赣皖区域利润表'!C14 -> 0 | D14: ='2025年中心利润表 '!D14+'2025年江苏分部利润表'!D14+'2025年浙江分部利润表'!D14+'2025年上海分部利润表'!D14+'2025年赣皖区域利润表'!D14 -> 0 | E14: ='2025年中心利润表 '!E14+'2025年江苏分部利润表'!E14+'2025年浙江分部利润表'!E14+'2025年上海分部利润表'!E14+'2025年赣皖区域利润表'!E14 -> 0 | F14: ='2025年中心利润表 '!F14+'2025年江苏分部利润表'!F14+'2025年浙江分部利润表'!F14+'2025年上海分部利润表'!F14+'2025年赣皖区域利润表'!F14 -> 0 | G14: ='2025年中心利润表 '!G14+'2025年江苏分部利润表'!G14+'2025年浙江分部利润表'!G14+'2025年上海分部利润表'!G14+'2025年赣皖区域利润表'!G14 -> 0 | H14: ='2025年中心利润表 '!H14+'2025年江苏分部利润表'!H14+'2025年浙江分部利润表'!H14+'2025年上海分部利润表'!H14+'2025年赣皖区域利润表'!H14 -> 0 | I14: ='2025年中心利润表 '!I14+'2025年江苏分部利润表'!I14+'2025年浙江分部利润表'!I14+'2025年上海分部利润表'!I14+'2025年赣皖区域利润表'!I14 -> 0 | J14: ='2025年中心利润表 '!J14+'2025年江苏分部利润表'!J14+'2025年浙江分部利润表'!J14+'2025年上海分部利润表'!J14+'2025年赣皖区域利润表'!J14 -> 92281.51 | ... Z14: ='2025年中心利润表 '!Z14+'2025年江苏分部利润表'!Z14+'2025年浙江分部利润表'!Z14+'2025年上海分部利润表'!Z14+'2025年赣皖区域利润表'!Z14 -> 84301.617 | AA14: =C14+E14+G14+I14+K14+M14+O14+Q14+S14+U14+W14+Y14 -> 1220607 | AB14: =D14+F14+H14+J14+L14+N14+P14+R14+T14+V14+X14+Z14 -> 896264.16 | AD14: =SUMIF($C$5:$Z$5,$AD$5,C14:Z14) -> 1220607 | AE14: =SUMIF($C$5:$Z$5,$AD$5,D14:AA14) -> 896264.16 | AH14: =SUM('[1]2024年全面预算利润表 (销售1中心)2.8亿'!E18:H18) -> 0
A15: 其他 | C15: ='2025年中心利润表 '!C15+'2025年江苏分部利润表'!C15+'2025年浙江分部利润表'!C15+'2025年上海分部利润表'!C15+'2025年赣皖区域利润表'!C15 -> 3986706.8 | D15: ='2025年中心利润表 '!D15+'2025年江苏分部利润表'!D15+'2025年浙江分部利润表'!D15+'2025年上海分部利润表'!D15+'2025年赣皖区域利润表'!D15 -> 853.98 | E15: ='2025年中心利润表 '!E15+'2025年江苏分部利润表'!E15+'2025年浙江分部利润表'!E15+'2025年上海分部利润表'!E15+'2025年赣皖区域利润表'!E15 -> 4955115 | F15: ='2025年中心利润表 '!F15+'2025年江苏分部利润表'!F15+'2025年浙江分部利润表'!F15+'2025年上海分部利润表'!F15+'2025年赣皖区域利润表'!F15 -> 530.97 | G15: ='2025年中心利润表 '!G15+'2025年江苏分部利润表'!G15+'2025年浙江分部利润表'!G15+'2025年上海分部利润表'!G15+'2025年赣皖区域利润表'!G15 -> 8700489.3 | H15: ='2025年中心利润表 '!H15+'2025年江苏分部利润表'!H15+'2025年浙江分部利润表'!H15+'2025年上海分部利润表'!H15+'2025年赣皖区域利润表'!H15 -> 0 | I15: ='2025年中心利润表 '!I15+'2025年江苏分部利润表'!I15+'2025年浙江分部利润表'!I15+'2025年上海分部利润表'!I15+'2025年赣皖区域利润表'!I15 -> 10237244 | J15: ='2025年中心利润表 '!J15+'2025年江苏分部利润表'!J15+'2025年浙江分部利润表'!J15+'2025年上海分部利润表'!J15+'2025年赣皖区域利润表'!J15 -> 0 | ... Z15: ='2025年中心利润表 '!Z15+'2025年江苏分部利润表'!Z15+'2025年浙江分部利润表'!Z15+'2025年上海分部利润表'!Z15+'2025年赣皖区域利润表'!Z15 -> 0 | AA15: =C15+E15+G15+I15+K15+M15+O15+Q15+S15+U15+W15+Y15 -> 123344000 | AB15: =D15+F15+H15+J15+L15+N15+P15+R15+T15+V15+X15+Z15 -> 7646.04 | AD15: =SUMIF($C$5:$Z$5,$AD$5,C15:Z15) -> 123344000 | AE15: =SUMIF($C$5:$Z$5,$AD$5,D15:AA15) -> 7646.04 | AF15: =AA15-AD15 -> 0 | AG15: =AB15-AE15 -> 0 | AH15: =SUM('[1]2024年全面预算利润表 (销售1中心)2.8亿'!E18:H18) -> 0
A16: 减：营业成本 | B16: 2 | C16: =SUM(C17:C25) -> 3382585.8 | D16: =SUM(D17:D25) -> 6952652.5 | E16: =SUM(E17:E25) -> 4215074 | F16: =SUM(F17:F25) -> 4306755.5 | G16: =SUM(G17:G25) -> 7282520.4 | H16: =SUM(H17:H25) -> 6051909.8 | I16: =SUM(I17:I25) -> 8454862.9 | J16: =SUM(J17:J25) -> 8553557.4 | ... Z16: =SUM(Z17:Z25) -> 10405260 | AA16: =C16+E16+G16+I16+K16+M16+O16+Q16+S16+U16+W16+Y16 -> 1.0100001e+08 | AB16: =D16+F16+H16+J16+L16+N16+P16+R16+T16+V16+X16+Z16 -> 85057035 | AD16: =SUMIF($C$5:$Z$5,$AD$5,C16:Z16) -> 1.0100001e+08 | AE16: =SUMIF($C$5:$Z$5,$AD$5,D16:AA16) -> 85057035 | AF16: =AA16-AD16 -> 0 | AG16: =AB16-AE16 -> 0 | AH16: =SUM('[1]2024年全面预算利润表 (销售1中心)2.8亿'!$E$16:$H$16) -> 29585058
A17: 中式汤底 | C17: ='2025年中心利润表 '!C17+'2025年江苏分部利润表'!C17+'2025年浙江分部利润表'!C17+'2025年上海分部利润表'!C17+'2025年赣皖区域利润表'!C17 -> 0 | D17: ='2025年中心利润表 '!D17+'2025年江苏分部利润表'!D17+'2025年浙江分部利润表'!D17+'2025年上海分部利润表'!D17+'2025年赣皖区域利润表'!D17 -> 1473240.4 | E17: ='2025年中心利润表 '!E17+'2025年江苏分部利润表'!E17+'2025年浙江分部利润表'!E17+'2025年上海分部利润表'!E17+'2025年赣皖区域利润表'!E17 -> 0 | F17: ='2025年中心利润表 '!F17+'2025年江苏分部利润表'!F17+'2025年浙江分部利润表'!F17+'2025年上海分部利润表'!F17+'2025年赣皖区域利润表'!F17 -> 1039771.2 | G17: ='2025年中心利润表 '!G17+'2025年江苏分部利润表'!G17+'2025年浙江分部利润表'!G17+'2025年上海分部利润表'!G17+'2025年赣皖区域利润表'!G17 -> 0 | H17: ='2025年中心利润表 '!H17+'2025年江苏分部利润表'!H17+'2025年浙江分部利润表'!H17+'2025年上海分部利润表'!H17+'2025年赣皖区域利润表'!H17 -> 1819851.8 | I17: ='2025年中心利润表 '!I17+'2025年江苏分部利润表'!I17+'2025年浙江分部利润表'!I17+'2025年上海分部利润表'!I17+'2025年赣皖区域利润表'!I17 -> 0 | J17: ='2025年中心利润表 '!J17+'2025年江苏分部利润表'!J17+'2025年浙江分部利润表'!J17+'2025年上海分部利润表'!J17+'2025年赣皖区域利润表'!J17 -> 2455648.6 | ... Z17: ='2025年中心利润表 '!Z17+'2025年江苏分部利润表'!Z17+'2025年浙江分部利润表'!Z17+'2025年上海分部利润表'!Z17+'2025年赣皖区域利润表'!Z17 -> 2529444.9 | AA17: =C17+E17+G17+I17+K17+M17+O17+Q17+S17+U17+W17+Y17 -> 0 | AB17: =D17+F17+H17+J17+L17+N17+P17+R17+T17+V17+X17+Z17 -> 22115149 | AD17: =SUMIF($C$5:$Z$5,$AD$5,C17:Z17) -> 0 | AE17: =SUMIF($C$5:$Z$5,$AD$5,D17:AA17) -> 22115149 | AF17: =AA17-AD17 -> 0 | AG17: =AB17-AE17 -> 0 | AH17: =SUM('[1]2024年全面预算利润表 (销售1中心)2.8亿'!E20:H20) -> 29005401
A18: 酱料 | C18: ='2025年中心利润表 '!C18+'2025年江苏分部利润表'!C18+'2025年浙江分部利润表'!C18+'2025年上海分部利润表'!C18+'2025年赣皖区域利润表'!C18 -> 0 | D18: ='2025年中心利润表 '!D18+'2025年江苏分部利润表'!D18+'2025年浙江分部利润表'!D18+'2025年上海分部利润表'!D18+'2025年赣皖区域利润表'!D18 -> 2551677.7 | E18: ='2025年中心利润表 '!E18+'2025年江苏分部利润表'!E18+'2025年浙江分部利润表'!E18+'2025年上海分部利润表'!E18+'2025年赣皖区域利润表'!E18 -> 0 | F18: ='2025年中心利润表 '!F18+'2025年江苏分部利润表'!F18+'2025年浙江分部利润表'!F18+'2025年上海分部利润表'!F18+'2025年赣皖区域利润表'!F18 -> 1712611.2 | G18: ='2025年中心利润表 '!G18+'2025年江苏分部利润表'!G18+'2025年浙江分部利润表'!G18+'2025年上海分部利润表'!G18+'2025年赣皖区域利润表'!G18 -> 0 | H18: ='2025年中心利润表 '!H18+'2025年江苏分部利润表'!H18+'2025年浙江分部利润表'!H18+'2025年上海分部利润表'!H18+'2025年赣皖区域利润表'!H18 -> 2745204.7 | I18: ='2025年中心利润表 '!I18+'2025年江苏分部利润表'!I18+'2025年浙江分部利润表'!I18+'2025年上海分部利润表'!I18+'2025年赣皖区域利润表'!I18 -> 0 | J18: ='2025年中心利润表 '!J18+'2025年江苏分部利润表'!J18+'2025年浙江分部利润表'!J18+'2025年上海分部利润表'!J18+'2025年赣皖区域利润表'!J18 -> 3044693.7 | ... Z18: ='2025年中心利润表 '!Z18+'2025年江苏分部利润表'!Z18+'2025年浙江分部利润表'!Z18+'2025年上海分部利润表'!Z18+'2025年赣皖区域利润表'!Z18 -> 3986784.2 | AA18: =C18+E18+G18+I18+K18+M18+O18+Q18+S18+U18+W18+Y18 -> 0 | AB18: =D18+F18+H18+J18+L18+N18+P18+R18+T18+V18+X18+Z18 -> 31561282 | AD18: =SUMIF($C$5:$Z$5,$AD$5,C18:Z18) -> 0 | AE18: =SUMIF($C$5:$Z$5,$AD$5,D18:AA18) -> 31561282 | AF18: =AA18-AD18 -> 0 | AG18: =AB18-AE18 -> 0 | AH18: =SUM('[1]2024年全面预算利润表 (销售1中心)2.8亿'!E21:H21) -> 579657.07
A19: 川味底料 | C19: ='2025年中心利润表 '!C19+'2025年江苏分部利润表'!C19+'2025年浙江分部利润表'!C19+'2025年上海分部利润表'!C19+'2025年赣皖区域利润表'!C19 -> 0 | D19: ='2025年中心利润表 '!D19+'2025年江苏分部利润表'!D19+'2025年浙江分部利润表'!D19+'2025年上海分部利润表'!D19+'2025年赣皖区域利润表'!D19 -> 2170913.3 | E19: ='2025年中心利润表 '!E19+'2025年江苏分部利润表'!E19+'2025年浙江分部利润表'!E19+'2025年上海分部利润表'!E19+'2025年赣皖区域利润表'!E19 -> 0 | F19: ='2025年中心利润表 '!F19+'2025年江苏分部利润表'!F19+'2025年浙江分部利润表'!F19+'2025年上海分部利润表'!F19+'2025年赣皖区域利润表'!F19 -> 1248175.7 | G19: ='2025年中心利润表 '!G19+'2025年江苏分部利润表'!G19+'2025年浙江分部利润表'!G19+'2025年上海分部利润表'!G19+'2025年赣皖区域利润表'!G19 -> 0 | H19: ='2025年中心利润表 '!H19+'2025年江苏分部利润表'!H19+'2025年浙江分部利润表'!H19+'2025年上海分部利润表'!H19+'2025年赣皖区域利润表'!H19 -> 1071829.2 | I19: ='2025年中心利润表 '!I19+'2025年江苏分部利润表'!I19+'2025年浙江分部利润表'!I19+'2025年上海分部利润表'!I19+'2025年赣皖区域利润表'!I19 -> 0 | J19: ='2025年中心利润表 '!J19+'2025年江苏分部利润表'!J19+'2025年浙江分部利润表'!J19+'2025年上海分部利润表'!J19+'2025年赣皖区域利润表'!J19 -> 2226700.7 | ... Z19: ='2025年中心利润表 '!Z19+'2025年江苏分部利润表'!Z19+'2025年浙江分部利润表'!Z19+'2025年上海分部利润表'!Z19+'2025年赣皖区域利润表'!Z19 -> 3427706.8 | AA19: =C19+E19+G19+I19+K19+M19+O19+Q19+S19+U19+W19+Y19 -> 0 | AB19: =D19+F19+H19+J19+L19+N19+P19+R19+T19+V19+X19+Z19 -> 24113807 | AD19: =SUMIF($C$5:$Z$5,$AD$5,C19:Z19) -> 0 | AE19: =SUMIF($C$5:$Z$5,$AD$5,D19:AA19) -> 24113807 | AF19: =AA19-AD19 -> 0 | AG19: =AB19-AE19 -> 0 | AH19: =SUM('[1]2024年全面预算利润表 (销售1中心)2.8亿'!E22:H22) -> 0
A20: 调味汁 | C20: ='2025年中心利润表 '!C20+'2025年江苏分部利润表'!C20+'2025年浙江分部利润表'!C20+'2025年上海分部利润表'!C20+'2025年赣皖区域利润表'!C20 -> 0 | D20: ='2025年中心利润表 '!D20+'2025年江苏分部利润表'!D20+'2025年浙江分部利润表'!D20+'2025年上海分部利润表'!D20+'2025年赣皖区域利润表'!D20 -> 332705.46 | E20: ='2025年中心利润表 '!E20+'2025年江苏分部利润表'!E20+'2025年浙江分部利润表'!E20+'2025年上海分部利润表'!E20+'2025年赣皖区域利润表'!E20 -> 0 | F20: ='2025年中心利润表 '!F20+'2025年江苏分部利润表'!F20+'2025年浙江分部利润表'!F20+'2025年上海分部利润表'!F20+'2025年赣皖区域利润表'!F20 -> 132104.21 | G20: ='2025年中心利润表 '!G20+'2025年江苏分部利润表'!G20+'2025年浙江分部利润表'!G20+'2025年上海分部利润表'!G20+'2025年赣皖区域利润表'!G20 -> 0 | H20: ='2025年中心利润表 '!H20+'2025年江苏分部利润表'!H20+'2025年浙江分部利润表'!H20+'2025年上海分部利润表'!H20+'2025年赣皖区域利润表'!H20 -> 181666.72 | I20: ='2025年中心利润表 '!I20+'2025年江苏分部利润表'!I20+'2025年浙江分部利润表'!I20+'2025年上海分部利润表'!I20+'2025年赣皖区域利润表'!I20 -> 0 | J20: ='2025年中心利润表 '!J20+'2025年江苏分部利润表'!J20+'2025年浙江分部利润表'!J20+'2025年上海分部利润表'!J20+'2025年赣皖区域利润表'!J20 -> 340450.67 | ... Z20: ='2025年中心利润表 '!Z20+'2025年江苏分部利润表'!Z20+'2025年浙江分部利润表'!Z20+'2025年上海分部利润表'!Z20+'2025年赣皖区域利润表'!Z20 -> 212481.71 | AA20: =C20+E20+G20+I20+K20+M20+O20+Q20+S20+U20+W20+Y20 -> 0 | AB20: =D20+F20+H20+J20+L20+N20+P20+R20+T20+V20+X20+Z20 -> 3157689.2 | AD20: =SUMIF($C$5:$Z$5,$AD$5,C20:Z20) -> 0 | AE20: =SUMIF($C$5:$Z$5,$AD$5,D20:AA20) -> 3157689.2 | AF20: =AA20-AD20 -> 0 | AG20: =AB20-AE20 -> 0 | AH20: =SUM('[1]2024年全面预算利润表 (销售1中心)2.8亿'!E23:H23) -> 6733315
A21: 复合调味粉 | C21: ='2025年中心利润表 '!C21+'2025年江苏分部利润表'!C21+'2025年浙江分部利润表'!C21+'2025年上海分部利润表'!C21+'2025年赣皖区域利润表'!C21 -> 0 | D21: ='2025年中心利润表 '!D21+'2025年江苏分部利润表'!D21+'2025年浙江分部利润表'!D21+'2025年上海分部利润表'!D21+'2025年赣皖区域利润表'!D21 -> 217523.13 | E21: ='2025年中心利润表 '!E21+'2025年江苏分部利润表'!E21+'2025年浙江分部利润表'!E21+'2025年上海分部利润表'!E21+'2025年赣皖区域利润表'!E21 -> 0 | F21: ='2025年中心利润表 '!F21+'2025年江苏分部利润表'!F21+'2025年浙江分部利润表'!F21+'2025年上海分部利润表'!F21+'2025年赣皖区域利润表'!F21 -> 68380.712 | G21: ='2025年中心利润表 '!G21+'2025年江苏分部利润表'!G21+'2025年浙江分部利润表'!G21+'2025年上海分部利润表'!G21+'2025年赣皖区域利润表'!G21 -> 0 | H21: ='2025年中心利润表 '!H21+'2025年江苏分部利润表'!H21+'2025年浙江分部利润表'!H21+'2025年上海分部利润表'!H21+'2025年赣皖区域利润表'!H21 -> 78636.423 | I21: ='2025年中心利润表 '!I21+'2025年江苏分部利润表'!I21+'2025年浙江分部利润表'!I21+'2025年上海分部利润表'!I21+'2025年赣皖区域利润表'!I21 -> 0 | J21: ='2025年中心利润表 '!J21+'2025年江苏分部利润表'!J21+'2025年浙江分部利润表'!J21+'2025年上海分部利润表'!J21+'2025年赣皖区域利润表'!J21 -> 284751.35 | ... Z21: ='2025年中心利润表 '!Z21+'2025年江苏分部利润表'!Z21+'2025年浙江分部利润表'!Z21+'2025年上海分部利润表'!Z21+'2025年赣皖区域利润表'!Z21 -> 77007.812 | AA21: =C21+E21+G21+I21+K21+M21+O21+Q21+S21+U21+W21+Y21 -> 0 | AB21: =D21+F21+H21+J21+L21+N21+P21+R21+T21+V21+X21+Z21 -> 1829644 | AD21: =SUMIF($C$5:$Z$5,$AD$5,C21:Z21) -> 0 | AE21: =SUMIF($C$5:$Z$5,$AD$5,D21:AA21) -> 1829644 | AF21: =AA21-AD21 -> 0 | AG21: =AB21-AE21 -> 0 | AH21: =SUM('[1]2024年全面预算利润表 (销售1中心)2.8亿'!E24:H24) -> 0
A22: 团餐 | C22: ='2025年中心利润表 '!C22+'2025年江苏分部利润表'!C22+'2025年浙江分部利润表'!C22+'2025年上海分部利润表'!C22+'2025年赣皖区域利润表'!C22 -> 0 | D22: ='2025年中心利润表 '!D22+'2025年江苏分部利润表'!D22+'2025年浙江分部利润表'!D22+'2025年上海分部利润表'!D22+'2025年赣皖区域利润表'!D22 -> 4247.996 | E22: ='2025年中心利润表 '!E22+'2025年江苏分部利润表'!E22+'2025年浙江分部利润表'!E22+'2025年上海分部利润表'!E22+'2025年赣皖区域利润表'!E22 -> 0 | F22: ='2025年中心利润表 '!F22+'2025年江苏分部利润表'!F22+'2025年浙江分部利润表'!F22+'2025年上海分部利润表'!F22+'2025年赣皖区域利润表'!F22 -> 10651.326 | G22: ='2025年中心利润表 '!G22+'2025年江苏分部利润表'!G22+'2025年浙江分部利润表'!G22+'2025年上海分部利润表'!G22+'2025年赣皖区域利润表'!G22 -> 0 | H22: ='2025年中心利润表 '!H22+'2025年江苏分部利润表'!H22+'2025年浙江分部利润表'!H22+'2025年上海分部利润表'!H22+'2025年赣皖区域利润表'!H22 -> 6748.6152 | I22: ='2025年中心利润表 '!I22+'2025年江苏分部利润表'!I22+'2025年浙江分部利润表'!I22+'2025年上海分部利润表'!I22+'2025年赣皖区域利润表'!I22 -> 0 | J22: ='2025年中心利润表 '!J22+'2025年江苏分部利润表'!J22+'2025年浙江分部利润表'!J22+'2025年上海分部利润表'!J22+'2025年赣皖区域利润表'!J22 -> 4176.9 | ... Z22: ='2025年中心利润表 '!Z22+'2025年江苏分部利润表'!Z22+'2025年浙江分部利润表'!Z22+'2025年上海分部利润表'!Z22+'2025年赣皖区域利润表'!Z22 -> 6817.2 | AA22: =C22+E22+G22+I22+K22+M22+O22+Q22+S22+U22+W22+Y22 -> 0 | AB22: =D22+F22+H22+J22+L22+N22+P22+R22+T22+V22+X22+Z22 -> 44210.498 | AD22: =SUMIF($C$5:$Z$5,$AD$5,C22:Z22) -> 0 | AE22: =SUMIF($C$5:$Z$5,$AD$5,D22:AA22) -> 44210.498 | AF22: =AA22-AD22 -> 0 | AG22: =AB22-AE22 -> 0 | AH22: =SUM('[1]2024年全面预算利润表 (销售1中心)2.8亿'!E25:H25) -> 0
A23: 预制菜 | C23: ='2025年中心利润表 '!C23+'2025年江苏分部利润表'!C23+'2025年浙江分部利润表'!C23+'2025年上海分部利润表'!C23+'2025年赣皖区域利润表'!C23 -> 0 | D23: ='2025年中心利润表 '!D23+'2025年江苏分部利润表'!D23+'2025年浙江分部利润表'!D23+'2025年上海分部利润表'!D23+'2025年赣皖区域利润表'!D23 -> 30967.084 | E23: ='2025年中心利润表 '!E23+'2025年江苏分部利润表'!E23+'2025年浙江分部利润表'!E23+'2025年上海分部利润表'!E23+'2025年赣皖区域利润表'!E23 -> 0 | F23: ='2025年中心利润表 '!F23+'2025年江苏分部利润表'!F23+'2025年浙江分部利润表'!F23+'2025年上海分部利润表'!F23+'2025年赣皖区域利润表'!F23 -> 7925.4 | G23: ='2025年中心利润表 '!G23+'2025年江苏分部利润表'!G23+'2025年浙江分部利润表'!G23+'2025年上海分部利润表'!G23+'2025年赣皖区域利润表'!G23 -> 0 | H23: ='2025年中心利润表 '!H23+'2025年江苏分部利润表'!H23+'2025年浙江分部利润表'!H23+'2025年上海分部利润表'!H23+'2025年赣皖区域利润表'!H23 -> 19220.134 | I23: ='2025年中心利润表 '!I23+'2025年江苏分部利润表'!I23+'2025年浙江分部利润表'!I23+'2025年上海分部利润表'!I23+'2025年赣皖区域利润表'!I23 -> 0 | J23: ='2025年中心利润表 '!J23+'2025年江苏分部利润表'!J23+'2025年浙江分部利润表'!J23+'2025年上海分部利润表'!J23+'2025年赣皖区域利润表'!J23 -> 18814.096 | ... Z23: ='2025年中心利润表 '!Z23+'2025年江苏分部利润表'!Z23+'2025年浙江分部利润表'!Z23+'2025年上海分部利润表'!Z23+'2025年赣皖区域利润表'!Z23 -> 4735.24 | AA23: =C23+E23+G23+I23+K23+M23+O23+Q23+S23+U23+W23+Y23 -> 0 | AB23: =D23+F23+H23+J23+L23+N23+P23+R23+T23+V23+X23+Z23 -> 188485.86 | AD23: =SUMIF($C$5:$Z$5,$AD$5,C23:Z23) -> 0 | AE23: =SUMIF($C$5:$Z$5,$AD$5,D23:AA23) -> 188485.86 | AF23: =AA23-AD23 -> 0 | AG23: =AB23-AE23 -> 0 | AH23: =SUM('[1]2024年全面预算利润表 (销售1中心)2.8亿'!E26:H26) -> 0
A24: 其他 | C24: ='2025年中心利润表 '!C24+'2025年江苏分部利润表'!C24+'2025年浙江分部利润表'!C24+'2025年上海分部利润表'!C24+'2025年赣皖区域利润表'!C24 -> 3320260 | D24: ='2025年中心利润表 '!D24+'2025年江苏分部利润表'!D24+'2025年浙江分部利润表'!D24+'2025年上海分部利润表'!D24+'2025年赣皖区域利润表'!D24 -> 4386.36 | E24: ='2025年中心利润表 '!E24+'2025年江苏分部利润表'!E24+'2025年浙江分部利润表'!E24+'2025年上海分部利润表'!E24+'2025年赣皖区域利润表'!E24 -> 4133487.5 | F24: ='2025年中心利润表 '!F24+'2025年江苏分部利润表'!F24+'2025年浙江分部利润表'!F24+'2025年上海分部利润表'!F24+'2025年赣皖区域利润表'!F24 -> 477.67 | G24: ='2025年中心利润表 '!G24+'2025年江苏分部利润表'!G24+'2025年浙江分部利润表'!G24+'2025年上海分部利润表'!G24+'2025年赣皖区域利润表'!G24 -> 7138634.4 | H24: ='2025年中心利润表 '!H24+'2025年江苏分部利润表'!H24+'2025年浙江分部利润表'!H24+'2025年上海分部利润表'!H24+'2025年赣皖区域利润表'!H24 -> 0 | I24: ='2025年中心利润表 '!I24+'2025年江苏分部利润表'!I24+'2025年浙江分部利润表'!I24+'2025年上海分部利润表'!I24+'2025年赣皖区域利润表'!I24 -> 8286368.7 | J24: ='2025年中心利润表 '!J24+'2025年江苏分部利润表'!J24+'2025年浙江分部利润表'!J24+'2025年上海分部利润表'!J24+'2025年赣皖区域利润表'!J24 -> 0 | ... Z24: ='2025年中心利润表 '!Z24+'2025年江苏分部利润表'!Z24+'2025年浙江分部利润表'!Z24+'2025年上海分部利润表'!Z24+'2025年赣皖区域利润表'!Z24 -> -18076.911 | AA24: =C24+E24+G24+I24+K24+M24+O24+Q24+S24+U24+W24+Y24 -> 98966577 | AB24: =D24+F24+H24+J24+L24+N24+P24+R24+T24+V24+X24+Z24 -> 227027.38 | AD24: =SUMIF($C$5:$Z$5,$AD$5,C24:Z24) -> 98966577 | AE24: =SUMIF($C$5:$Z$5,$AD$5,D24:AA24) -> 227027.38 | AF24: =AA24-AD24 -> 0 | AG24: =AB24-AE24 -> 0 | AH24: =SUM('[1]2024年全面预算利润表 (销售1中心)2.8亿'!E27:H27) -> 7312972.1
A25: 运费 | C25: ='2025年中心利润表 '!C25+'2025年江苏分部利润表'!C25+'2025年浙江分部利润表'!C25+'2025年上海分部利润表'!C25+'2025年赣皖区域利润表'!C25 -> 62325.76 | D25: ='2025年中心利润表 '!D25+'2025年江苏分部利润表'!D25+'2025年浙江分部利润表'!D25+'2025年上海分部利润表'!D25+'2025年赣皖区域利润表'!D25 -> 166991.03 | E25: ='2025年中心利润表 '!E25+'2025年江苏分部利润表'!E25+'2025年浙江分部利润表'!E25+'2025年上海分部利润表'!E25+'2025年赣皖区域利润表'!E25 -> 81586.56 | F25: ='2025年中心利润表 '!F25+'2025年江苏分部利润表'!F25+'2025年浙江分部利润表'!F25+'2025年上海分部利润表'!F25+'2025年赣皖区域利润表'!F25 -> 86658.07 | G25: ='2025年中心利润表 '!G25+'2025年江苏分部利润表'!G25+'2025年浙江分部利润表'!G25+'2025年上海分部利润表'!G25+'2025年赣皖区域利润表'!G25 -> 143885.94 | H25: ='2025年中心利润表 '!H25+'2025年江苏分部利润表'!H25+'2025年浙江分部利润表'!H25+'2025年上海分部利润表'!H25+'2025年赣皖区域利润表'!H25 -> 128752.16 | I25: ='2025年中心利润表 '!I25+'2025年江苏分部利润表'!I25+'2025年浙江分部利润表'!I25+'2025年上海分部利润表'!I25+'2025年赣皖区域利润表'!I25 -> 168494.16 | J25: ='2025年中心利润表 '!J25+'2025年江苏分部利润表'!J25+'2025年浙江分部利润表'!J25+'2025年上海分部利润表'!J25+'2025年赣皖区域利润表'!J25 -> 178321.47 | ... Z25: ='2025年中心利润表 '!Z25+'2025年江苏分部利润表'!Z25+'2025年浙江分部利润表'!Z25+'2025年上海分部利润表'!Z25+'2025年赣皖区域利润表'!Z25 -> 178358.9 | AA25: =C25+E25+G25+I25+K25+M25+O25+Q25+S25+U25+W25+Y25 -> 2033432 | AB25: =D25+F25+H25+J25+L25+N25+P25+R25+T25+V25+X25+Z25 -> 1819739.1 | AD25: =SUMIF($C$5:$Z$5,$AD$5,C25:Z25) -> 2033432 | AE25: =SUMIF($C$5:$Z$5,$AD$5,D25:AA25) -> 1819739.1 | AF25: =AA25-AD25 -> 0 | AG25: =AB25-AE25 -> 0 | AH25: =SUM('[1]2024年全面预算利润表 (销售1中心)2.8亿'!E28:H28) -> 0.7299
A26: 毛利 | B26: 3 | C26: =C6-C16 -> 604121.05 | D26: =D6-D16 -> 1808716 | E26: =E6-E16 -> 740040.96 | F26: =F6-F16 -> 1129317.9 | G26: =G6-G16 -> 1417968.9 | H26: =H6-H16 -> 1502757.3 | I26: =I6-I16 -> 1782381.1 | J26: =J6-J16 -> 2010946.9 | ... Z26: =Z6-Z16 -> 2769067 | AA26: =C26+E26+G26+I26+K26+M26+O26+Q26+S26+U26+W26+Y26 -> 21123384 | AB26: =D26+F26+H26+J26+L26+N26+P26+R26+T26+V26+X26+Z26 -> 21821860 | AD26: =SUMIF($C$5:$Z$5,$AD$5,C26:Z26) -> 21123384 | AE26: =SUMIF($C$5:$Z$5,$AD$5,D26:AA26) -> 21821860 | AF26: =AD6-AD16-AA26 -> 0 | AG26: =AE6-AE16-AB26 -> 0 | AH26: =AH6-AH16 -> 6733315
A27: 毛利率 | B27: 4 | C27: =IF(C6=0,,C26/C6) -> 0.15153385 | D27: =IF(D6=0,,D26/D6) -> 0.20644218 | E27: =IF(E6=0,,E26/E6) -> 0.1493489 | F27: =IF(F6=0,,F26/F6) -> 0.20774515 | G27: =IF(G6=0,,G26/G6) -> 0.16297577 | H27: =IF(H6=0,,H26/H6) -> 0.19891774 | I27: =IF(I6=0,,I26/I6) -> 0.17410752 | J27: =IF(J6=0,,J26/J6) -> 0.19034939 | ... AB27: =IF(AB6=0,,AB26/AB6) -> 0.20417371 | AD27: =AD26/AD6 -> 0.17296755 | AE27: =AE26/AE6 -> 0.20417371 | AF27: =AA27-AD27 -> 0 | AG27: =AB27-AE27 -> 0 | AH27: =AH26/AH6 -> 0.18539693
A28: 税金及附加 | B28: 5 | C28: ='2025年中心利润表 '!C28+'2025年江苏分部利润表'!C28+'2025年浙江分部利润表'!C28+'2025年上海分部利润表'!C28+'2025年赣皖区域利润表'!C28 -> 35117.14 | D28: ='2025年中心利润表 '!D28+'2025年江苏分部利润表'!D28+'2025年浙江分部利润表'!D28+'2025年上海分部利润表'!D28+'2025年赣皖区域利润表'!D28 -> 83233.005 | E28: ='2025年中心利润表 '!E28+'2025年江苏分部利润表'!E28+'2025年浙江分部利润表'!E28+'2025年上海分部利润表'!E28+'2025年赣皖区域利润表'!E28 -> 47073.6 | F28: ='2025年中心利润表 '!F28+'2025年江苏分部利润表'!F28+'2025年浙江分部利润表'!F28+'2025年上海分部利润表'!F28+'2025年赣皖区域利润表'!F28 -> 51642.694 | G28: ='2025年中心利润表 '!G28+'2025年江苏分部利润表'!G28+'2025年浙江分部利润表'!G28+'2025年上海分部利润表'!G28+'2025年赣皖区域利润表'!G28 -> 82351.24 | H28: ='2025年中心利润表 '!H28+'2025年江苏分部利润表'!H28+'2025年浙江分部利润表'!H28+'2025年上海分部利润表'!H28+'2025年赣皖区域利润表'!H28 -> 71769.332 | I28: ='2025年中心利润表 '!I28+'2025年江苏分部利润表'!I28+'2025年浙江分部利润表'!I28+'2025年上海分部利润表'!I28+'2025年赣皖区域利润表'!I28 -> 97760.84 | J28: ='2025年中心利润表 '!J28+'2025年江苏分部利润表'!J28+'2025年浙江分部利润表'!J28+'2025年上海分部利润表'!J28+'2025年赣皖区域利润表'!J28 -> 100362.8 | ... Z28: ='2025年中心利润表 '!Z28+'2025年江苏分部利润表'!Z28+'2025年浙江分部利润表'!Z28+'2025年上海分部利润表'!Z28+'2025年赣皖区域利润表'!Z28 -> 125156.11 | AA28: =C28+E28+G28+I28+K28+M28+O28+Q28+S28+U28+W28+Y28 -> 1161420.4 | AB28: =D28+F28+H28+J28+L28+N28+P28+R28+T28+V28+X28+Z28 -> 1015349.5 | AD28: =SUMIF($C$5:$Z$5,$AD$5,C28:Z28) -> 1161420.4 | AE28: =SUMIF($C$5:$Z$5,$AD$5,D28:AA28) -> 1015349.5 | AF28: =AA28-AD28 -> 0 | AG28: =AB28-AE28 -> 0 | AH28: =SUM('[1]2024年全面预算利润表 (销售1中心)2.8亿'!$E$33:$H$33) -> 319601.69
A29: 销售费用 | B29: 6 | C29: =SUM(C30:C101)-C30-C33-C42-C53-C65 -> 736578.18 | D29: =SUM(D30:D101)-D30-D33-D42-D53-D65 -> 661019.17 | E29: =SUM(E30:E101)-E30-E33-E42-E53-E65 -> 574743.98 | F29: =SUM(F30:F101)-F30-F33-F42-F53-F65 -> 471368.5 | G29: =SUM(G30:G101)-G30-G33-G42-G53-G65 -> 748602.01 | H29: =SUM(H30:H101)-H30-H33-H42-H53-H65 -> 484266.56 | I29: =SUM(I30:I101)-I30-I33-I42-I53-I65 -> 709616.68 | J29: =SUM(J30:J101)-J30-J33-J42-J53-J65 -> 714586.55 | ... Z29: =SUM(Z30:Z101)-Z30-Z33-Z42-Z53-Z65 -> 508612.48 | AA29: =C29+E29+G29+I29+K29+M29+O29+Q29+S29+U29+W29+Y29 -> 9055651.2 | AB29: =D29+F29+H29+J29+L29+N29+P29+R29+T29+V29+X29+Z29 -> 6438464.7 | AD29: =SUMIF($C$5:$Z$5,$AD$5,C29:Z29) -> 9055651.2 | AE29: =SUMIF($C$5:$Z$5,$AD$5,D29:AA29) -> 6438464.7 | AF29: =AD29-(SUM(AA30:AA101)-SUM(AA30,AA33,AA42,AA53,AA65)) -> 0 | AG29: =AE29-(SUM(AB30:AB101)-SUM(AB30,AB33,AB42,AB53,AB65)) -> 0 | AH29: =SUM('[1]2024年全面预算利润表 (销售1中心)2.8亿'!E34:H34) -> 2909788.3
A30: 职工薪酬 | C30: =SUM(C31:C32) -> 453892.92 | D30: =SUM(D31:D32) -> 370435.67 | E30: =SUM(E31:E32) -> 343278.72 | F30: =SUM(F31:F32) -> 269606.58 | G30: =SUM(G31:G32) -> 430336.75 | H30: =SUM(H31:H32) -> 235131.7 | I30: =SUM(I31:I32) -> 480067.42 | J30: =SUM(J31:J32) -> 402799.83 | ... Z30: =SUM(Z31:Z32) -> 263429.06 | AA30: =C30+E30+G30+I30+K30+M30+O30+Q30+S30+U30+W30+Y30 -> 6060592 | AB30: =D30+F30+H30+J30+L30+N30+P30+R30+T30+V30+X30+Z30 -> 3548826.3 | AD30: =SUMIF($C$5:$Z$5,$AD$5,C30:Z30) -> 6060592 | AE30: =SUMIF($C$5:$Z$5,$AD$5,D30:AA30) -> 3548826.3 | AF30: =AA30-AD30 -> 0 | AG30: =AB30-AE30 -> 0 | AH30: =SUM('[1]2024年全面预算利润表 (销售1中心)2.8亿'!E35:H35) -> 1979870
A31: 工资 | C31: ='2025年中心利润表 '!C31+'2025年江苏分部利润表'!C31+'2025年浙江分部利润表'!C31+'2025年上海分部利润表'!C31+'2025年赣皖区域利润表'!C31 -> 181191 | D31: ='2025年中心利润表 '!D31+'2025年江苏分部利润表'!D31+'2025年浙江分部利润表'!D31+'2025年上海分部利润表'!D31+'2025年赣皖区域利润表'!D31 -> 210924.98 | E31: ='2025年中心利润表 '!E31+'2025年江苏分部利润表'!E31+'2025年浙江分部利润表'!E31+'2025年上海分部利润表'!E31+'2025年赣皖区域利润表'!E31 -> 181241 | F31: ='2025年中心利润表 '!F31+'2025年江苏分部利润表'!F31+'2025年浙江分部利润表'!F31+'2025年上海分部利润表'!F31+'2025年赣皖区域利润表'!F31 -> 203875.58 | G31: ='2025年中心利润表 '!G31+'2025年江苏分部利润表'!G31+'2025年浙江分部利润表'!G31+'2025年上海分部利润表'!G31+'2025年赣皖区域利润表'!G31 -> 181241 | H31: ='2025年中心利润表 '!H31+'2025年江苏分部利润表'!H31+'2025年浙江分部利润表'!H31+'2025年上海分部利润表'!H31+'2025年赣皖区域利润表'!H31 -> 101305.7 | I31: ='2025年中心利润表 '!I31+'2025年江苏分部利润表'!I31+'2025年浙江分部利润表'!I31+'2025年上海分部利润表'!I31+'2025年赣皖区域利润表'!I31 -> 191671 | J31: ='2025年中心利润表 '!J31+'2025年江苏分部利润表'!J31+'2025年浙江分部利润表'!J31+'2025年上海分部利润表'!J31+'2025年赣皖区域利润表'!J31 -> 171658.83 | ... Z31: ='2025年中心利润表 '!Z31+'2025年江苏分部利润表'!Z31+'2025年浙江分部利润表'!Z31+'2025年上海分部利润表'!Z31+'2025年赣皖区域利润表'!Z31 -> 157536.06 | AA31: =C31+E31+G31+I31+K31+M31+O31+Q31+S31+U31+W31+Y31 -> 2272612 | AB31: =D31+F31+H31+J31+L31+N31+P31+R31+T31+V31+X31+Z31 -> 1986631.6 | AD31: =SUMIF($C$5:$Z$5,$AD$5,C31:Z31) -> 2272612 | AE31: =SUMIF($C$5:$Z$5,$AD$5,D31:AA31) -> 1986631.6 | AF31: =AA31-AD31 -> 0 | AG31: =AB31-AE31 -> 0 | AH31: =SUM('[1]2024年全面预算利润表 (销售1中心)2.8亿'!E36:H36) -> 893600
A32: 奖金及提成 | C32: ='2025年中心利润表 '!C32+'2025年江苏分部利润表'!C32+'2025年浙江分部利润表'!C32+'2025年上海分部利润表'!C32+'2025年赣皖区域利润表'!C32 -> 272701.92 | D32: ='2025年中心利润表 '!D32+'2025年江苏分部利润表'!D32+'2025年浙江分部利润表'!D32+'2025年上海分部利润表'!D32+'2025年赣皖区域利润表'!D32 -> 159510.69 | E32: ='2025年中心利润表 '!E32+'2025年江苏分部利润表'!E32+'2025年浙江分部利润表'!E32+'2025年上海分部利润表'!E32+'2025年赣皖区域利润表'!E32 -> 162037.72 | F32: ='2025年中心利润表 '!F32+'2025年江苏分部利润表'!F32+'2025年浙江分部利润表'!F32+'2025年上海分部利润表'!F32+'2025年赣皖区域利润表'!F32 -> 65731 | G32: ='2025年中心利润表 '!G32+'2025年江苏分部利润表'!G32+'2025年浙江分部利润表'!G32+'2025年上海分部利润表'!G32+'2025年赣皖区域利润表'!G32 -> 249095.75 | H32: ='2025年中心利润表 '!H32+'2025年江苏分部利润表'!H32+'2025年浙江分部利润表'!H32+'2025年上海分部利润表'!H32+'2025年赣皖区域利润表'!H32 -> 133826 | I32: ='2025年中心利润表 '!I32+'2025年江苏分部利润表'!I32+'2025年浙江分部利润表'!I32+'2025年上海分部利润表'!I32+'2025年赣皖区域利润表'!I32 -> 288396.42 | J32: ='2025年中心利润表 '!J32+'2025年江苏分部利润表'!J32+'2025年浙江分部利润表'!J32+'2025年上海分部利润表'!J32+'2025年赣皖区域利润表'!J32 -> 231141 | ... Z32: ='2025年中心利润表 '!Z32+'2025年江苏分部利润表'!Z32+'2025年浙江分部利润表'!Z32+'2025年上海分部利润表'!Z32+'2025年赣皖区域利润表'!Z32 -> 105893 | AA32: =C32+E32+G32+I32+K32+M32+O32+Q32+S32+U32+W32+Y32 -> 3787980 | AB32: =D32+F32+H32+J32+L32+N32+P32+R32+T32+V32+X32+Z32 -> 1562194.7 | AD32: =SUMIF($C$5:$Z$5,$AD$5,C32:Z32) -> 3787980 | AE32: =SUMIF($C$5:$Z$5,$AD$5,D32:AA32) -> 1562194.7 | AF32: =AA32-AD32 -> 0 | AG32: =AB32-AE32 -> 0 | AH32: =SUM('[1]2024年全面预算利润表 (销售1中心)2.8亿'!E37:H37) -> 1086270
A33: 社保 | C33: =SUM(C34:C38) -> 30201.6 | D33: =SUM(D34:D38) -> 28007.26 | E33: =SUM(E34:E38) -> 30201.6 | F33: =SUM(F34:F38) -> 24135.4 | G33: =SUM(G34:G38) -> 30201.6 | H33: =SUM(H34:H38) -> 25465.02 | I33: =SUM(I34:I38) -> 30201.6 | J33: =SUM(J34:J38) -> 25465.02 | ... Z33: =SUM(Z34:Z38) -> 26385.87 | AA33: =C33+E33+G33+I33+K33+M33+O33+Q33+S33+U33+W33+Y33 -> 362419.2 | AB33: =D33+F33+H33+J33+L33+N33+P33+R33+T33+V33+X33+Z33 -> 310549.07 | AD33: =SUMIF($C$5:$Z$5,$AD$5,C33:Z33) -> 362419.2 | AE33: =SUMIF($C$5:$Z$5,$AD$5,D33:AA33) -> 310549.07 | AF33: =AA33-AD33 -> 0 | AG33: =AB33-AE33 -> 0 | AH33: =SUM('[1]2024年全面预算利润表 (销售1中心)2.8亿'!E38:H38) -> 121836.62
A34: 养老 | C34: ='2025年中心利润表 '!C34+'2025年江苏分部利润表'!C34+'2025年浙江分部利润表'!C34+'2025年上海分部利润表'!C34+'2025年赣皖区域利润表'!C34 -> 18720 | D34: ='2025年中心利润表 '!D34+'2025年江苏分部利润表'!D34+'2025年浙江分部利润表'!D34+'2025年上海分部利润表'!D34+'2025年赣皖区域利润表'!D34 -> 17743.68 | E34: ='2025年中心利润表 '!E34+'2025年江苏分部利润表'!E34+'2025年浙江分部利润表'!E34+'2025年上海分部利润表'!E34+'2025年赣皖区域利润表'!E34 -> 18720 | F34: ='2025年中心利润表 '!F34+'2025年江苏分部利润表'!F34+'2025年浙江分部利润表'!F34+'2025年上海分部利润表'!F34+'2025年赣皖区域利润表'!F34 -> 15362.88 | G34: ='2025年中心利润表 '!G34+'2025年江苏分部利润表'!G34+'2025年浙江分部利润表'!G34+'2025年上海分部利润表'!G34+'2025年赣皖区域利润表'!G34 -> 18720 | H34: ='2025年中心利润表 '!H34+'2025年江苏分部利润表'!H34+'2025年浙江分部利润表'!H34+'2025年上海分部利润表'!H34+'2025年赣皖区域利润表'!H34 -> 16168.32 | I34: ='2025年中心利润表 '!I34+'2025年江苏分部利润表'!I34+'2025年浙江分部利润表'!I34+'2025年上海分部利润表'!I34+'2025年赣皖区域利润表'!I34 -> 18720 | J34: ='2025年中心利润表 '!J34+'2025年江苏分部利润表'!J34+'2025年浙江分部利润表'!J34+'2025年上海分部利润表'!J34+'2025年赣皖区域利润表'!J34 -> 16168.32 | ... Z34: ='2025年中心利润表 '!Z34+'2025年江苏分部利润表'!Z34+'2025年浙江分部利润表'!Z34+'2025年上海分部利润表'!Z34+'2025年赣皖区域利润表'!Z34 -> 16752.96 | AA34: =C34+E34+G34+I34+K34+M34+O34+Q34+S34+U34+W34+Y34 -> 224640 | AB34: =D34+F34+H34+J34+L34+N34+P34+R34+T34+V34+X34+Z34 -> 198411.84 | AD34: =SUMIF($C$5:$Z$5,$AD$5,C34:Z34) -> 224640 | AE34: =SUMIF($C$5:$Z$5,$AD$5,D34:AA34) -> 198411.84 | AF34: =AA34-AD34 -> 0 | AG34: =AB34-AE34 -> 0 | AH34: =SUM('[1]2024年全面预算利润表 (销售1中心)2.8亿'!E39:H39) -> 73521.84
A35: 医疗 | C35: ='2025年中心利润表 '!C35+'2025年江苏分部利润表'!C35+'2025年浙江分部利润表'!C35+'2025年上海分部利润表'!C35+'2025年赣皖区域利润表'!C35 -> 9984 | D35: ='2025年中心利润表 '!D35+'2025年江苏分部利润表'!D35+'2025年浙江分部利润表'!D35+'2025年上海分部利润表'!D35+'2025年赣皖区域利润表'!D35 -> 9475.56 | E35: ='2025年中心利润表 '!E35+'2025年江苏分部利润表'!E35+'2025年浙江分部利润表'!E35+'2025年上海分部利润表'!E35+'2025年赣皖区域利润表'!E35 -> 9984 | F35: ='2025年中心利润表 '!F35+'2025年江苏分部利润表'!F35+'2025年浙江分部利润表'!F35+'2025年上海分部利润表'!F35+'2025年赣皖区域利润表'!F35 -> 8112.3 | G35: ='2025年中心利润表 '!G35+'2025年江苏分部利润表'!G35+'2025年浙江分部利润表'!G35+'2025年上海分部利润表'!G35+'2025年赣皖区域利润表'!G35 -> 9984 | H35: ='2025年中心利润表 '!H35+'2025年江苏分部利润表'!H35+'2025年浙江分部利润表'!H35+'2025年上海分部利润表'!H35+'2025年赣皖区域利润表'!H35 -> 8589.42 | I35: ='2025年中心利润表 '!I35+'2025年江苏分部利润表'!I35+'2025年浙江分部利润表'!I35+'2025年上海分部利润表'!I35+'2025年赣皖区域利润表'!I35 -> 9984 | J35: ='2025年中心利润表 '!J35+'2025年江苏分部利润表'!J35+'2025年浙江分部利润表'!J35+'2025年上海分部利润表'!J35+'2025年赣皖区域利润表'!J35 -> 8589.42 | ... Z35: ='2025年中心利润表 '!Z35+'2025年江苏分部利润表'!Z35+'2025年浙江分部利润表'!Z35+'2025年上海分部利润表'!Z35+'2025年赣皖区域利润表'!Z35 -> 8900.01 | AA35: =C35+E35+G35+I35+K35+M35+O35+Q35+S35+U35+W35+Y35 -> 119808 | AB35: =D35+F35+H35+J35+L35+N35+P35+R35+T35+V35+X35+Z35 -> 103456.68 | AD35: =SUMIF($C$5:$Z$5,$AD$5,C35:Z35) -> 119808 | AE35: =SUMIF($C$5:$Z$5,$AD$5,D35:AA35) -> 103456.68 | AF35: =AA35-AD35 -> 0 | AG35: =AB35-AE35 -> 0 | AH35: =SUM('[1]2024年全面预算利润表 (销售1中心)2.8亿'!E40:H40) -> 44638.26
A36: 工伤 | C36: ='2025年中心利润表 '!C36+'2025年江苏分部利润表'!C36+'2025年浙江分部利润表'!C36+'2025年上海分部利润表'!C36+'2025年赣皖区域利润表'!C36 -> 249.6 | D36: ='2025年中心利润表 '!D36+'2025年江苏分部利润表'!D36+'2025年浙江分部利润表'!D36+'2025年上海分部利润表'!D36+'2025年赣皖区域利润表'!D36 -> 233.53 | E36: ='2025年中心利润表 '!E36+'2025年江苏分部利润表'!E36+'2025年浙江分部利润表'!E36+'2025年上海分部利润表'!E36+'2025年赣皖区域利润表'!E36 -> 249.6 | F36: ='2025年中心利润表 '!F36+'2025年江苏分部利润表'!F36+'2025年浙江分部利润表'!F36+'2025年上海分部利润表'!F36+'2025年赣皖区域利润表'!F36 -> 173.57 | G36: ='2025年中心利润表 '!G36+'2025年江苏分部利润表'!G36+'2025年浙江分部利润表'!G36+'2025年上海分部利润表'!G36+'2025年赣皖区域利润表'!G36 -> 249.6 | H36: ='2025年中心利润表 '!H36+'2025年江苏分部利润表'!H36+'2025年浙江分部利润表'!H36+'2025年上海分部利润表'!H36+'2025年赣皖区域利润表'!H36 -> 198.74 | I36: ='2025年中心利润表 '!I36+'2025年江苏分部利润表'!I36+'2025年浙江分部利润表'!I36+'2025年上海分部利润表'!I36+'2025年赣皖区域利润表'!I36 -> 249.6 | J36: ='2025年中心利润表 '!J36+'2025年江苏分部利润表'!J36+'2025年浙江分部利润表'!J36+'2025年上海分部利润表'!J36+'2025年赣皖区域利润表'!J36 -> 198.74 | ... Z36: ='2025年中心利润表 '!Z36+'2025年江苏分部利润表'!Z36+'2025年浙江分部利润表'!Z36+'2025年上海分部利润表'!Z36+'2025年赣皖区域利润表'!Z36 -> 209.37 | AA36: =C36+E36+G36+I36+K36+M36+O36+Q36+S36+U36+W36+Y36 -> 2995.2 | AB36: =D36+F36+H36+J36+L36+N36+P36+R36+T36+V36+X36+Z36 -> 2482.26 | AD36: =SUMIF($C$5:$Z$5,$AD$5,C36:Z36) -> 2995.2 | AE36: =SUMIF($C$5:$Z$5,$AD$5,D36:AA36) -> 2482.26 | AF36: =AA36-AD36 -> 0 | AG36: =AB36-AE36 -> 0 | AH36: =SUM('[1]2024年全面预算利润表 (销售1中心)2.8亿'!E41:H41) -> 1050.74
A37: 失业 | C37: ='2025年中心利润表 '!C37+'2025年江苏分部利润表'!C37+'2025年浙江分部利润表'!C37+'2025年上海分部利润表'!C37+'2025年赣皖区域利润表'!C37 -> 624 | D37: ='2025年中心利润表 '!D37+'2025年江苏分部利润表'!D37+'2025年浙江分部利润表'!D37+'2025年上海分部利润表'!D37+'2025年赣皖区域利润表'!D37 -> 554.49 | E37: ='2025年中心利润表 '!E37+'2025年江苏分部利润表'!E37+'2025年浙江分部利润表'!E37+'2025年上海分部利润表'!E37+'2025年赣皖区域利润表'!E37 -> 624 | F37: ='2025年中心利润表 '!F37+'2025年江苏分部利润表'!F37+'2025年浙江分部利润表'!F37+'2025年上海分部利润表'!F37+'2025年赣皖区域利润表'!F37 -> 486.65 | G37: ='2025年中心利润表 '!G37+'2025年江苏分部利润表'!G37+'2025年浙江分部利润表'!G37+'2025年上海分部利润表'!G37+'2025年赣皖区域利润表'!G37 -> 624 | H37: ='2025年中心利润表 '!H37+'2025年江苏分部利润表'!H37+'2025年浙江分部利润表'!H37+'2025年上海分部利润表'!H37+'2025年赣皖区域利润表'!H37 -> 508.54 | I37: ='2025年中心利润表 '!I37+'2025年江苏分部利润表'!I37+'2025年浙江分部利润表'!I37+'2025年上海分部利润表'!I37+'2025年赣皖区域利润表'!I37 -> 624 | J37: ='2025年中心利润表 '!J37+'2025年江苏分部利润表'!J37+'2025年浙江分部利润表'!J37+'2025年上海分部利润表'!J37+'2025年赣皖区域利润表'!J37 -> 508.54 | ... Z37: ='2025年中心利润表 '!Z37+'2025年江苏分部利润表'!Z37+'2025年浙江分部利润表'!Z37+'2025年上海分部利润表'!Z37+'2025年赣皖区域利润表'!Z37 -> 523.53 | AA37: =C37+E37+G37+I37+K37+M37+O37+Q37+S37+U37+W37+Y37 -> 7488 | AB37: =D37+F37+H37+J37+L37+N37+P37+R37+T37+V37+X37+Z37 -> 6198.29 | AD37: =SUMIF($C$5:$Z$5,$AD$5,C37:Z37) -> 7488 | AE37: =SUMIF($C$5:$Z$5,$AD$5,D37:AA37) -> 6198.29 | AF37: =AA37-AD37 -> 0 | AG37: =AB37-AE37 -> 0 | AH37: =SUM('[1]2024年全面预算利润表 (销售1中心)2.8亿'!E42:H42) -> 2625.78
A38: 生育 | C38: ='2025年中心利润表 '!C38+'2025年江苏分部利润表'!C38+'2025年浙江分部利润表'!C38+'2025年上海分部利润表'!C38+'2025年赣皖区域利润表'!C38 -> 624 | D38: ='2025年中心利润表 '!D38+'2025年江苏分部利润表'!D38+'2025年浙江分部利润表'!D38+'2025年上海分部利润表'!D38+'2025年赣皖区域利润表'!D38 -> 0 | E38: ='2025年中心利润表 '!E38+'2025年江苏分部利润表'!E38+'2025年浙江分部利润表'!E38+'2025年上海分部利润表'!E38+'2025年赣皖区域利润表'!E38 -> 624 | F38: ='2025年中心利润表 '!F38+'2025年江苏分部利润表'!F38+'2025年浙江分部利润表'!F38+'2025年上海分部利润表'!F38+'2025年赣皖区域利润表'!F38 -> 0 | G38: ='2025年中心利润表 '!G38+'2025年江苏分部利润表'!G38+'2025年浙江分部利润表'!G38+'2025年上海分部利润表'!G38+'2025年赣皖区域利润表'!G38 -> 624 | H38: ='2025年中心利润表 '!H38+'2025年江苏分部利润表'!H38+'2025年浙江分部利润表'!H38+'2025年上海分部利润表'!H38+'2025年赣皖区域利润表'!H38 -> 0 | I38: ='2025年中心利润表 '!I38+'2025年江苏分部利润表'!I38+'2025年浙江分部利润表'!I38+'2025年上海分部利润表'!I38+'2025年赣皖区域利润表'!I38 -> 624 | J38: ='2025年中心利润表 '!J38+'2025年江苏分部利润表'!J38+'2025年浙江分部利润表'!J38+'2025年上海分部利润表'!J38+'2025年赣皖区域利润表'!J38 -> 0 | ... Z38: ='2025年中心利润表 '!Z38+'2025年江苏分部利润表'!Z38+'2025年浙江分部利润表'!Z38+'2025年上海分部利润表'!Z38+'2025年赣皖区域利润表'!Z38 -> 0 | AA38: =C38+E38+G38+I38+K38+M38+O38+Q38+S38+U38+W38+Y38 -> 7488 | AB38: =D38+F38+H38+J38+L38+N38+P38+R38+T38+V38+X38+Z38 -> 0 | AD38: =SUMIF($C$5:$Z$5,$AD$5,C38:Z38) -> 7488 | AE38: =SUMIF($C$5:$Z$5,$AD$5,D38:AA38) -> 0 | AF38: =AA38-AD38 -> 0 | AG38: =AB38-AE38 -> 0 | AH38: =SUM('[1]2024年全面预算利润表 (销售1中心)2.8亿'!E43:H43) -> 0
A39: 公积金 | C39: ='2025年中心利润表 '!C39+'2025年江苏分部利润表'!C39+'2025年浙江分部利润表'!C39+'2025年上海分部利润表'!C39+'2025年赣皖区域利润表'!C39 -> 6456 | D39: ='2025年中心利润表 '!D39+'2025年江苏分部利润表'!D39+'2025年浙江分部利润表'!D39+'2025年上海分部利润表'!D39+'2025年赣皖区域利润表'!D39 -> 6067 | E39: ='2025年中心利润表 '!E39+'2025年江苏分部利润表'!E39+'2025年浙江分部利润表'!E39+'2025年上海分部利润表'!E39+'2025年赣皖区域利润表'!E39 -> 6456 | F39: ='2025年中心利润表 '!F39+'2025年江苏分部利润表'!F39+'2025年浙江分部利润表'!F39+'2025年上海分部利润表'!F39+'2025年赣皖区域利润表'!F39 -> 5500 | G39: ='2025年中心利润表 '!G39+'2025年江苏分部利润表'!G39+'2025年浙江分部利润表'!G39+'2025年上海分部利润表'!G39+'2025年赣皖区域利润表'!G39 -> 6456 | H39: ='2025年中心利润表 '!H39+'2025年江苏分部利润表'!H39+'2025年浙江分部利润表'!H39+'2025年上海分部利润表'!H39+'2025年赣皖区域利润表'!H39 -> 5649 | I39: ='2025年中心利润表 '!I39+'2025年江苏分部利润表'!I39+'2025年浙江分部利润表'!I39+'2025年上海分部利润表'!I39+'2025年赣皖区域利润表'!I39 -> 6456 | J39: ='2025年中心利润表 '!J39+'2025年江苏分部利润表'!J39+'2025年浙江分部利润表'!J39+'2025年上海分部利润表'!J39+'2025年赣皖区域利润表'!J39 -> 5649 | ... Z39: ='2025年中心利润表 '!Z39+'2025年江苏分部利润表'!Z39+'2025年浙江分部利润表'!Z39+'2025年上海分部利润表'!Z39+'2025年赣皖区域利润表'!Z39 -> 5111 | AA39: =C39+E39+G39+I39+K39+M39+O39+Q39+S39+U39+W39+Y39 -> 77472 | AB39: =D39+F39+H39+J39+L39+N39+P39+R39+T39+V39+X39+Z39 -> 63753 | AD39: =SUMIF($C$5:$Z$5,$AD$5,C39:Z39) -> 77472 | AE39: =SUMIF($C$5:$Z$5,$AD$5,D39:AA39) -> 63753 | AF39: =AA39-AD39 -> 0 | AG39: =AB39-AE39 -> 0 | AH39: =SUM('[1]2024年全面预算利润表 (销售1中心)2.8亿'!E44:H44) -> 27707
